Workbook

Sheet Instruction
B2: 这个文件主要用来整理MIA回归模型的结果，更新成给CS的模板
B3: • 自动更新"2A 回归Syntax"，Column A为X变量，Column B为Y变量（填充回归变量，多组回归同时进行时，按每组间间隔三行的形式向下填充）
B4: • 自动更新 2A Regression、2B RotationRule、2B FL、2C 均值、seenvsnoseen、Sample_Check
B5: • 需要维护2A 回归syntax C列及以后的公式
B6: • 更新“2D Mapping“，column A填写"2A Regression结果"对应的regression第几个regression结果表格（column L），column B填写table 对应的KPI，column C填写这个KPI是基于Total样本or部分样本
B7: • 2E.Analysis_MIA中，需要手动填写B列黄色部分(指回归x变量中除了factor以外的部分）
A8: 待更新：
A9: 2E.Analysis_MIA/2E.ROE Scan中，标准化系数的y变量，均是以变量名/变量名加d呈现，如果想要用一些标准化术语/标签，需要修改对应公式
A10: 程序写入表格只是写入内容，目前的格式有些错乱，需要规范表格格式，看起来不那么乱
A11: 目前某些公式的结果还空白/报错，需要检查公式的逻辑
A20: 存在的问题：
A21: 当回归同时进行两组（x变量只有factor/ factor+dy变量时），2E.Analysis_MIA的标准化系数后半部分结果错误
A31: 按道理来说，只有前半部分y对应的brand dispo应该为0，现在整行都为0

Sheet 2A 回归syntax
A1: X变量 | B1: Y变量 | C1: SYNTAX1
A2: dLevel_B7_T2B | B2: dLevel_ABA | C2: ="REGRESSION /MISSING PAIRWISE /STATISTICS COEFF OUTS R ANOVA /CRITERIA=PIN(.05) POUT(.10) /NOORIGIN /DEPENDENT "&B2&" /METHOD=ENTER "&_xlfn.TEXTJOIN(" ",,$A$2:$A$40) &". " -> REGRESSION /MISSING PAIRWISE /STATISTICS COEFF OUTS R ANOVA /CRITERIA=PIN(.05) POUT(.10) /NOORIGIN /DEPENDENT dLevel_ABA /METHOD=ENTER dLevel_B7_T2B Factor1 Factor2 Factor3 Factor4 Factor5 Factor6 Factor7 Factor8 Factor9 Factor10 Factor11 Factor12 Factor13 Factor14 Factor15 Factor16 Factor17 Factor18 Factor19 Factor20 Factor21 Factor22 Factor23 Factor24 Factor25 Factor26 Factor27 Factor1 Factor2 Factor3 Factor4 Factor5 Factor6 Factor7 Factor8.
A3: Factor1 | B3: dLevel_B6_T2B | C3: ="REGRESSION /MISSING PAIRWISE /STATISTICS COEFF OUTS R ANOVA /CRITERIA=PIN(.05) POUT(.10) /NOORIGIN /DEPENDENT "&B3&" /METHOD=ENTER "&_xlfn.TEXTJOIN(" ",,$A$2:$A$12) &". " -> REGRESSION /MISSING PAIRWISE /STATISTICS COEFF OUTS R ANOVA /CRITERIA=PIN(.05) POUT(.10) /NOORIGIN /DEPENDENT dLevel_B6_T2B /METHOD=ENTER dLevel_B7_T2B Factor1 Factor2 Factor3 Factor4 Factor5 Factor6 Factor7 Factor8 Factor9 Factor10.
A4: Factor2 | C4: ="REGRESSION /MISSING PAIRWISE /STATISTICS COEFF OUTS R ANOVA /CRITERIA=PIN(.05) POUT(.10) /NOORIGIN /DEPENDENT "&B4&" /METHOD=ENTER "&_xlfn.TEXTJOIN(" ",,$A$2:$A$12) &". " -> REGRESSION /MISSING PAIRWISE /STATISTICS COEFF OUTS R ANOVA /CRITERIA=PIN(.05) POUT(.10) /NOORIGIN /DEPENDENT /METHOD=ENTER dLevel_B7_T2B Factor1 Factor2 Factor3 Factor4 Factor5 Factor6 Factor7 Factor8 Factor9 Factor10.
A5: Factor3 | C5: ="REGRESSION /MISSING PAIRWISE /STATISTICS COEFF OUTS R ANOVA /CRITERIA=PIN(.05) POUT(.10) /NOORIGIN /DEPENDENT "&B5&" /METHOD=ENTER "&_xlfn.TEXTJOIN(" ",,$A$2:$A$12) &". " -> REGRESSION /MISSING PAIRWISE /STATISTICS COEFF OUTS R ANOVA /CRITERIA=PIN(.05) POUT(.10) /NOORIGIN /DEPENDENT /METHOD=ENTER dLevel_B7_T2B Factor1 Factor2 Factor3 Factor4 Factor5 Factor6 Factor7 Factor8 Factor9 Factor10.
A6: Factor4 | C6: ="REGRESSION /MISSING PAIRWISE /STATISTICS COEFF OUTS R ANOVA /CRITERIA=PIN(.05) POUT(.10) /NOORIGIN /DEPENDENT "&B6&" /METHOD=ENTER "&_xlfn.TEXTJOIN(" ",,$A$2:$A$12) &". " -> REGRESSION /MISSING PAIRWISE /STATISTICS COEFF OUTS R ANOVA /CRITERIA=PIN(.05) POUT(.10) /NOORIGIN /DEPENDENT /METHOD=ENTER dLevel_B7_T2B Factor1 Factor2 Factor3 Factor4 Factor5 Factor6 Factor7 Factor8 Factor9 Factor10.
A7: Factor5 | C7: ="REGRESSION /MISSING PAIRWISE /STATISTICS COEFF OUTS R ANOVA /CRITERIA=PIN(.05) POUT(.10) /NOORIGIN /DEPENDENT "&B7&" /METHOD=ENTER "&_xlfn.TEXTJOIN(" ",,$A$2:$A$12) &". " -> REGRESSION /MISSING PAIRWISE /STATISTICS COEFF OUTS R ANOVA /CRITERIA=PIN(.05) POUT(.10) /NOORIGIN /DEPENDENT /METHOD=ENTER dLevel_B7_T2B Factor1 Factor2 Factor3 Factor4 Factor5 Factor6 Factor7 Factor8 Factor9 Factor10.
A8: Factor6 | C8: ="REGRESSION /MISSING PAIRWISE /STATISTICS COEFF OUTS R ANOVA /CRITERIA=PIN(.05) POUT(.10) /NOORIGIN /DEPENDENT "&B8&" /METHOD=ENTER "&_xlfn.TEXTJOIN(" ",,$A$2:$A$12) &". " -> REGRESSION /MISSING PAIRWISE /STATISTICS COEFF OUTS R ANOVA /CRITERIA=PIN(.05) POUT(.10) /NOORIGIN /DEPENDENT /METHOD=ENTER dLevel_B7_T2B Factor1 Factor2 Factor3 Factor4 Factor5 Factor6 Factor7 Factor8 Factor9 Factor10.
A9: Factor7 | C9: ="REGRESSION /MISSING PAIRWISE /STATISTICS COEFF OUTS R ANOVA /CRITERIA=PIN(.05) POUT(.10) /NOORIGIN /DEPENDENT "&B9&" /METHOD=ENTER "&_xlfn.TEXTJOIN(" ",,$A$2:$A$12) &". " -> REGRESSION /MISSING PAIRWISE /STATISTICS COEFF OUTS R ANOVA /CRITERIA=PIN(.05) POUT(.10) /NOORIGIN /DEPENDENT /METHOD=ENTER dLevel_B7_T2B Factor1 Factor2 Factor3 Factor4 Factor5 Factor6 Factor7 Factor8 Factor9 Factor10.
A10: Factor8 | C10: ="REGRESSION /MISSING PAIRWISE /STATISTICS COEFF OUTS R ANOVA /CRITERIA=PIN(.05) POUT(.10) /NOORIGIN /DEPENDENT "&B10&" /METHOD=ENTER "&_xlfn.TEXTJOIN(" ",,$A$2:$A$12) &". " -> REGRESSION /MISSING PAIRWISE /STATISTICS COEFF OUTS R ANOVA /CRITERIA=PIN(.05) POUT(.10) /NOORIGIN /DEPENDENT /METHOD=ENTER dLevel_B7_T2B Factor1 Factor2 Factor3 Factor4 Factor5 Factor6 Factor7 Factor8 Factor9 Factor10.
A11: Factor9 | C11: ="REGRESSION /MISSING PAIRWISE /STATISTICS COEFF OUTS R ANOVA /CRITERIA=PIN(.05) POUT(.10) /NOORIGIN /DEPENDENT "&B11&" /METHOD=ENTER "&_xlfn.TEXTJOIN(" ",,$A$2:$A$12) &". " -> REGRESSION /MISSING PAIRWISE /STATISTICS COEFF OUTS R ANOVA /CRITERIA=PIN(.05) POUT(.10) /NOORIGIN /DEPENDENT /METHOD=ENTER dLevel_B7_T2B Factor1 Factor2 Factor3 Factor4 Factor5 Factor6 Factor7 Factor8 Factor9 Factor10.
A12: Factor10
A13: Factor11
A14: Factor12
A15: Factor13
A16: Factor14
A17: Factor15
A18: Factor16
A19: Factor17
A20: Factor18
A21: Factor19
A22: Factor20
A23: Factor21
... A29: Factor27
A33: Factor1 | B33: dLevel_ABA
A34: Factor2 | B34: dLevel_B6_T2B
A35: Factor3 | B35: dLevel_B7_T2B
A36: Factor4
A37: Factor5
A38: Factor6
A39: Factor7
A40: Factor8
A41: Factor9
A42: Factor10
A43: Factor11
A44: Factor12
A45: Factor13
A46: Factor14
A47: Factor15
... A59: Factor27

Sheet 2A Regression
A1: Dependent Variable: dLevel_ABA
A2: Model Summary
A3: Model | B3: R | C3: R Square | D3: Adjusted R Square | E3: Std. Error of the Estimate
A4: 1 | B4: 0.82950938 | C4: 0.68808582 | D4: 0.68643516 | E4: 0.24569055
A5: a. Predictors: (Constant), dLevel_B7_T2B, Factor1, Factor2, Factor3, Factor4, Factor5, Factor6, Factor7, Factor8, Factor9, Factor10, Factor11, Factor12, Factor13, Factor14, Factor15, Factor16, Factor17, Factor18, Factor19, Factor20, Factor21, Factor22, Factor23, Factor24, Factor25, Factor26, Factor27
A7: Coefficientsa
A8: Model | C8: Unstandardized Coefficients | E8: Standardized Coefficients | F8: t | G8: Sig. | H8: 95.0% Confidence Interval for B
C9: B | D9: Std. Error | E9: Beta | H9: Lower Bound | I9: Upper Bound
A10: 1 | B10: constant | C10: 0.081144592 | D10: 0.0037539155 | F10: 21.615988 | G10: 0 | H10: 0.073785369 | I10: 0.088503815
B11: dLevel_B7_T2B | C11: 0.77821858 | D11: 0.012610449 | E11: 0.69514539 | F11: 61.712203 | G11: 0 | H11: 0.7534969 | I11: 0.80294026
B12: Factor1 | C12: 0.017417586 | D12: 0.003493815 | E12: 0.039697503 | F12: 4.985263 | G12: 6.3851448e-07 | H12: 0.010568268 | I12: 0.024266905
B13: Factor2 | C13: 0.0083588182 | D13: 0.0034293304 | E13: 0.019051102 | F13: 2.4374491 | G13: 0.014824014 | H13: 0.0016359162 | I13: 0.01508172
B14: Factor3 | C14: 0.0071924806 | D14: 0.0034167211 | E14: 0.016392829 | F14: 2.1050827 | G14: 0.03533113 | H14: 0.00049429808 | I14: 0.013890663
B15: Factor4 | C15: 0.018287504 | D15: 0.0035096121 | E15: 0.041680188 | F15: 5.2106911 | G15: 1.9527614e-07 | H15: 0.011407217 | I15: 0.025167792
B16: Factor5 | C16: 0.0072419159 | D16: 0.0034217198 | E16: 0.016505501 | F16: 2.116455 | G16: 0.034352694 | H16: 0.00053393391 | I16: 0.013949898
B17: Factor6 | C17: 0.013956 | D17: 0.0034096656 | E17: 0.031807987 | F17: 4.0930701 | G17: 4.3203878e-05 | H17: 0.0072716492 | I17: 0.020640351
B18: Factor7 | C18: 0.024350554 | D18: 0.0035148935 | E18: 0.05549886 | F18: 6.9278212 | G18: 4.7832849e-12 | H18: 0.017459913 | I18: 0.031241195
B19: Factor8 | C19: 0.011050653 | D19: 0.0035141739 | E19: 0.025186229 | F19: 3.1445947 | G19: 0.0016723814 | H19: 0.0041614225 | I19: 0.017939883
B20: Factor9 | C20: 0.0058628194 | D20: 0.0034155793 | E20: 0.013362316 | F20: 1.7164934 | G20: 0.086130299 | H20: -0.0008331247 | I20: 0.012558763
B21: Factor10 | C21: 0.010017393 | D21: 0.0033853907 | E21: 0.022831263 | F21: 2.9590065 | G21: 0.0031000018 | H21: 0.0033806311 | I21: 0.016654155
B22: Factor11 | C22: 0.017374026 | D22: 0.0034132108 | E22: 0.039598221 | F22: 5.0902294 | G22: 3.700083e-07 | H22: 0.010682725 | I22: 0.024065327
... B38: Factor27 | C38: 0.0049704165 | D38: 0.0034137105 | E38: 0.011328385 | F38: 1.4560158 | G38: 0.14544758 | H38: -0.0017218641 | I38: 0.011662697
B39: a. Dependent Variable: dLevel_ABA
A41: Dependent Variable: dLevel_B6_T2B
A42: Model Summary
A43: Model | B43: R | C43: R Square | D43: Adjusted R Square | E43: Std. Error of the Estimate
A44: 2 | B44: 0.82430068 | C44: 0.67947161 | D44: 0.67777537 | E44: 0.2281935
A45: a. Predictors: (Constant), dLevel_B7_T2B, Factor1, Factor2, Factor3, Factor4, Factor5, Factor6, Factor7, Factor8, Factor9, Factor10, Factor11, Factor12, Factor13, Factor14, Factor15, Factor16, Factor17, Factor18, Factor19, Factor20, Factor21, Factor22, Factor23, Factor24, Factor25, Factor26, Factor27
A47: Coefficientsa
A48: Model | C48: Unstandardized Coefficients | E48: Standardized Coefficients | F48: t | G48: Sig. | H48: 95.0% Confidence Interval for B
C49: B | D49: Std. Error | E49: Beta | H49: Lower Bound | I49: Upper Bound
A50: 2 | B50: constant | C50: 0.040791302 | D50: 0.0034865774 | F50: 11.699526 | G50: 0 | H50: 0.033956172 | I50: 0.047626432
B51: dLevel_B7_T2B | C51: 0.68309411 | D51: 0.011712386 | E51: 0.66597123 | F51: 58.322372 | G51: 0 | H51: 0.660133 | I51: 0.70605521
B52: Factor1 | C52: 0.017175866 | D52: 0.0032450001 | E52: 0.042726247 | F52: 5.2930249 | G52: 1.2516437e-07 | H52: 0.010814328 | I52: 0.023537405
B53: Factor2 | C53: 0.0033178859 | D53: 0.0031851078 | E53: 0.0082534884 | F53: 1.0416871 | G53: 0.29760435 | H53: -0.0029262391 | I53: 0.0095620109
B54: Factor3 | C54: 0.0034818246 | D54: 0.0031733965 | E54: 0.0086612981 | F54: 1.0971918 | G54: 0.27260749 | H54: -0.0027393414 | I54: 0.0097029906
B55: Factor4 | C55: 0.020736362 | D55: 0.0032596722 | E55: 0.051583245 | F55: 6.3614869 | G55: 2.1661606e-10 | H55: 0.01434606 | I55: 0.027126664
B56: Factor5 | C56: 0.018992089 | D56: 0.0031780392 | E56: 0.047244238 | F56: 5.97604 | G56: 2.4357143e-09 | H56: 0.012761822 | I56: 0.025222357
B57: Factor6 | C57: 0.013768782 | D57: 0.0031668434 | E57: 0.034250871 | F57: 4.3477937 | G57: 1.4009477e-05 | H57: 0.0075604625 | I57: 0.019977101
B58: Factor7 | C58: 0.031322793 | D58: 0.0032645775 | E58: 0.07791778 | F58: 9.5947463 | G58: 0 | H58: 0.024922874 | I58: 0.037722711
...

Sheet 2B RotationRule
B2: VariableID | C2: Name | D2: Lable | E2: Factor1 | F2: Factor2 | G2: Factor3 | H2: Factor4 | I2: Factor5 | J2: Factor6 | K2: Factor7 | L2: Factor8 | M2: Factor9 | N2: Factor10 | O2: Factor11 | P2: Factor12 | Q2: Factor13 | R2: Factor14 | S2: Factor15 | T2: Factor16 | U2: Factor17 | V2: Factor18 | W2: Factor19 | X2: Factor20 | Y2: Factor21 | Z2: Factor22 | AA2: Factor23 | AB2: Factor24 | AC2: Factor25 | AD2: Factor26 | AE2: Factor27
B3: 1 | C3: dLevel_T2_1 | D3: T2: Official brand website | E3: 1
B4: 2 | C4: dLevel_T2_2 | D4: T2: Streaming / content platforms | F4: 1
B5: 3 | C5: dLevel_T2_3 | D5: T2: CTV device / smart TV platform | G5: 1
B6: 4 | C6: dLevel_T2_4 | D6: T2: Social media | H6: 1
B7: 5 | C7: dLevel_T2_5 | D7: T2: Influencers /Content creators | I7: 1
B8: 6 | C8: dLevel_T2_6 | D8: T2: Online forums & communities | J8: 1
B9: 7 | C9: dLevel_T2_7 | D9: T2: Search engines | K9: 1
B10: 8 | C10: dLevel_T2_8 | D10: T2: Online retail platforms / retailer websites | L10: 1
B11: 9 | C11: dLevel_T2_9 | D11: T2: Online news or digital media websites | M11: 1
B12: 10 | C12: dLevel_T2_10 | D12: T2: AI assistants / AI chatbot tools | N12: 1
B13: 11 | C13: dLevel_T2_11 | D13: T2: Deals sites / price comparison websites | O13: 1
B14: 12 | C14: dLevel_T2_12 | D14: T2: Second-hand or rental websites | P14: 1
B15: 13 | C15: dLevel_T2_13 | D15: T2: Podcasts | Q15: 1
B16: 14 | C16: dLevel_T2_14 | D16: T2: TV commercials / Home shopping channels / Radio | R16: 1
B17: 15 | C17: dLevel_T2_15 | D17: T2: Newspapers /Magazines | S17: 1
B18: 16 | C18: dLevel_T2_16 | D18: T2: Large garden centers / chains | T18: 1
B19: 17 | C19: dLevel_T2_17 | D19: T2: Local specialized lawn equipment dealers / independent specialists | U19: 1
B20: 18 | C20: dLevel_T2_18 | D20: T2: Offline DIY home improvement retail chains | V20: 1
B21: 19 | C21: dLevel_T2_19 | D21: T2: Consumer electronics retailers | W21: 1
B22: 20 | C22: dLevel_T2_21 | D22: T2: In-store sales representatives / staff recommendations | X22: 1
B23: 21 | C23: dLevel_T2_22 | D23: T2: Outdoor advertising / OOH / DOOH | Y23: 1
B24: 22 | C24: dLevel_T2_23 | D24: T2: Community groups or local organizations | Z24: 1
B25: 23 | C25: dLevel_T2_24 | D25: T2: Recommendations from friends, family, colleagues or neighbors | AA25: 1
B26: 24 | C26: dLevel_T2_25 | D26: T2: Live events, Trade shows, exhibitions, or garden expos | AB26: 1
B27: 25 | C27: dLevel_T2_26 | D27: T2: Sponsorships, brand ambassadors, or official partnerships | AC27: 1
B28: 26 | C28: dLevel_T2_27 | D28: T2: Local lawn care workshops | AD28: 1
B29: 27 | C29: dLevel_T2_28 | D29: T2: Recommendations from professional landscapers or garden contractors | AE29: 1

Sheet 2B FL
A1: Spend time = 00:00:02
A2: Factor Result
A3: TIME= 2026/08/12 17:32:09
A4: Rotation Method= Procrustes Method
A7: Total Variance Explained
A8: Initial Eigenvalues
A9: Extraction Method: Principal Component Analysis.
A11: Component | B11: Total | C11: % of Variance | D11: Cumulative %
A12: Factor1 | B12: 7.4007614 | C12: 0.27410227 | D12: 0.27410227
A13: Factor2 | B13: 2.9301255 | C13: 0.10852317 | D13: 0.38262544
A14: Factor3 | B14: 1.2048552 | C14: 0.044624268 | D14: 0.42724971
A15: Factor4 | B15: 1.0963101 | C15: 0.040604079 | D15: 0.46785379
A16: Factor5 | B16: 0.9669632 | C16: 0.035813452 | D16: 0.50366724
A17: Factor6 | B17: 0.92015725 | C17: 0.034079898 | D17: 0.53774714
A18: Factor7 | B18: 0.90478225 | C18: 0.033510454 | D18: 0.57125759
A19: Factor8 | B19: 0.8829751 | C19: 0.032702781 | D19: 0.60396037
A20: Factor9 | B20: 0.84008277 | C20: 0.031114177 | D20: 0.63507455
A21: Factor10 | B21: 0.83297055 | C21: 0.030850761 | D21: 0.66592531
A22: Factor11 | B22: 0.7811391 | C22: 0.028931078 | D22: 0.69485639
A23: Factor12 | B23: 0.7461586 | C23: 0.027635504 | D23: 0.72249189
... A38: Factor27 | B38: 0.22612799 | C38: 0.0083751106 | D38: 1
A40: Component Matrix
A41: Extraction Method: Principal Component Analysis.
A43: VariableID | B43: Variable | C43: Lable | D43: Factor1 | E43: Factor2 | F43: Factor3 | G43: Factor4 | H43: Factor5 | I43: Factor6 | J43: Factor7 | K43: Factor8 | L43: Factor9 | M43: Factor10 | N43: Factor11 | O43: Factor12 | P43: Factor13 | Q43: Factor14 | R43: Factor15 | S43: Factor16 | T43: Factor17 | U43: Factor18 | V43: Factor19 | W43: Factor20 | X43: Factor21 | Y43: Factor22 | Z43: Factor23 | AA43: Factor24 | AB43: Factor25 | AC43: Factor26 | AD43: Factor27
A44: 1 | B44: dLevel_T2_1 | C44: T2: Official brand website | D44: -0.666891 | E44: -0.56058163 | F44: 0.1020363 | G44: -0.049793957 | H44: 0.037856085 | I44: -0.019017312 | J44: -0.068058286 | K44: -0.042687714 | L44: 0.013188448 | M44: 0.06797674 | N44: 0.023419026 | O44: 0.032736457 | P44: -0.012920864 | Q44: -0.061931419 | R44: -0.024221541 | S44: -0.0097090899 | T44: -0.05603474 | U44: 0.024550181 | V44: 0.065427527 | W44: 0.13355133 | X44: -0.062890694 | Y44: -0.013637226 | Z44: 0.14086325 | AA44: -0.063741099 | AB44: -0.12201808 | AC44: 0.019562136 | AD44: -0.37361688
A45: 2 | B45: dLevel_T2_2 | C45: T2: Streaming / content platforms | D45: -0.51896614 | E45: 0.26436211 | F45: -0.26579553 | G45: 0.160091 | H45: -0.25814369 | I45: 0.10169215 | J45: -0.1251975 | K45: 0.13002519 | L45: -0.032242833 | M45: 0.012232578 | N45: -0.2549641 | O45: -0.054568447 | P45: -0.10712406 | Q45: -0.32961821 | R45: 0.063637941 | S45: -0.23315856 | T45: -0.25628762 | U45: -0.023280227 | V45: -0.061604405 | W45: -0.24835494 | X45: 0.25442186 | Y45: 0.060052088 | Z45: 0.022880665 | AA45: -0.016499313 | AB45: 0.045449504 | AC45: 0.015765152 | AD45: -0.063973879
A46: 3 | B46: dLevel_T2_3 | C46: T2: CTV device / smart TV platform | D46: -0.48041173 | E46: 0.36011673 | F46: -0.14740117 | G46: 0.14309808 | H46: -0.3384841 | I46: -0.11683178 | J46: -0.041998134 | K46: 0.025960214 | L46: -0.2042264 | M46: -0.40160019 | N46: 0.1174907 | O46: -0.070755193 | P46: 0.0027288711 | Q46: 0.05132942 | R46: -0.084147271 | S46: -0.076629902 | T46: 0.11359606 | U46: -0.090390993 | V46: -0.22013088 | W46: -0.057082376 | X46: -0.31008981 | Y46: -0.22075533 | Z46: 0.076680216 | AA46: 0.045995201 | AB46: -0.029590009 | AC46: 0.038015573 | AD46: -0.035573565
A47: 4 | B47: dLevel_T2_4 | C47: T2: Social media | D47: -0.74756684 | E47: -0.41673523 | F47: -0.052644053 | G47: 0.0547731 | H47: 0.0022589144 | I47: -0.015907527 | J47: -0.10470209 | K47: 0.083259889 | L47: -0.044591946 | M47: -0.11728624 | N47: 0.044787815 | O47: 0.014945005 | P47: 0.015699147 | Q47: -0.011542239 | R47: 0.018071042 | S47: 0.00058048366 | T47: -0.059573591 | U47: 0.053943784 | V47: 0.032777849 | W47: -0.019799426 | X47: 0.057404069 | Y47: -0.045050352 | Z47: 0.013362883 | AA47: -0.011697609 | AB47: -0.25420874 | AC47: -0.35749016 | AD47: 0.13741908
A48: 5 | B48: dLevel_T2_5 | C48: T2: Influencers /Content creators | D48: -0.55824189 | E48: 0.073427332 | F48: -0.10909729 | G48: 0.46598098 | H48: -0.088063121 | I48: 0.085264034 | J48: -0.034827926 | K48: -0.044702087 | L48: -0.0071683151 | M48: 0.095458308 | N48: 0.058728347 | O48: -0.11472722 | P48: 0.11338298 | Q48: 0.30857392 | R48: 0.18076842 | S48: 0.099937511 | T48: 0.35970481 | U48: -0.10013029 | V48: -0.10462258 | W48: 0.061595173 | X48: 0.29480573 | Y48: 0.06926827 | Z48: 0.035890854 | AA48: -0.10178018 | AB48: -0.0040445264 | AC48: 0.019550744 | AD48: -0.03572582
A49: 6 | B49: dLevel_T2_6 | C49: T2: Online forums & communities | D49: -0.52010265 | E49: 0.21340792 | F49: -0.32035951 | G49: 0.31768001 | H49: -0.09432475 | I49: 0.22238681 | J49: 0.17391981 | K49: -0.13008711 | L49: 0.1428575 | M49: 0.02886483 | N49: -0.074908294 | O49: -0.082057118 | P49: -0.19531745 | Q49: -0.1057016 | R49: 0.073268567 | S49: 0.058476445 | T49: -0.034559578 | U49: 0.30389254 | V49: 0.11142195 | W49: 0.34308146 | X49: -0.19418125 | Y49: 0.083326186 | Z49: -0.071571581 | AA49: 0.09245861 | AB49: 0.022671883 | AC49: -0.018080886 | AD49: 0.018806862
A50: 7 | B50: dLevel_T2_7 | C50: T2: Search engines | D50: -0.69828638 | E50: -0.51844817 | F50: 0.038378904 | G50: 0.036906035 | H50: -0.021679655 | I50: 0.013561187 | J50: -0.024218655 | K50: 0.039615628 | L50: -0.041969967 | M50: -0.0070954949 | N50: 0.0052765975 | O50: -0.0024620033 | P50: -0.017460826 | Q50: -0.030353204 | R50: -0.0075299653 | S50: -0.073412174 | T50: -0.033306606 | U50: 0.015121409 | V50: 0.13735202 | W50: 0.030832261 | X50: 0.048036886 | Y50: -0.040294122 | Z50: 0.081382541 | AA50: 0.031951445 | AB50: -0.19424688 | AC50: 0.34749834 | AD50: 0.1955211
A51: 8 | B51: dLevel_T2_8 | C51: T2: Online retail platforms / retailer websites | D51: -0.71280385 | E51: -0.39224075 | F51: -0.089062442 | G51: -0.092598551 | H51: -0.035543414 | I51: 0.0067029381 | J51: -0.055349251 | K51: -0.00045918366 | L51: 0.032103459 | M51: -0.011161008 | N51: 0.054063191 | O51: -0.0076970911 | P51: 0.13209396 | Q51: 0.056859256 | R51: 0.033064768 | S51: 0.079311029 | T51: -0.067482063 | U51: -0.10773617 | V51: -0.035318691 | W51: -0.0081706085 | X51: 0.086163318 | Y51: -0.17547531 | Z51: -0.42815135 | AA51: 0.19228417 | AB51: 0.050196365 | AC51: 0.035331863 | AD51: -0.072326237
A52: 9 | B52: dLevel_T2_9 | C52: T2: Online news or digital media websites | D52: -0.39911672 | E52: 0.31616393 | F52: -0.18669194 | G52: 0.0078552925 | H52: 0.2420558 | I52: -0.26755079 | J52: 0.38880389 | K52: 0.095284186 | L52: 0.086763969 | M52: -0.023670949 | N52: 0.36953398 | O52: 0.13499475 | P52: -0.13425119 | Q52: -0.33965629 | R52: 0.1007181 | S52: -0.0090624236 | T52: 0.22308525 | U52: -0.11484946 | V52: 0.16362186 | W52: -0.091896416 | X52: 0.083063353 | Y52: -0.045531019 | Z52: -0.011347043 | AA52: 0.01053042 | AB52: -0.026459919 | AC52: 0.0011559705 | AD52: -0.028933996
A53: 10 | B53: dLevel_T2_10 | C53: T2: AI assistants / AI chatbot tools | D53: -0.47436458 | E53: 0.39406157 | F53: 0.0005639908 | G53: -0.042941916 | H53: 0.22555971 | I53: -0.18136325 | J53: -0.093176456 | K53: 0.093129906 | L53: -0.0074134801 | M53: -0.21275962 | N53: 0.12073705 | O53: 0.2698802 | P53: 0.19734638 | Q53: 0.048737407 | R53: 0.26147566 | S53: 0.17249092 | T53: -0.26822033 | U53: 0.27840573 | V53: -0.25741788 | W53: 0.045231769 | X53: 0.031240805 | Y53: 0.11963774 | Z53: -0.007534188 | AA53: -0.072206964 | AB53: -0.013013856 | AC53: 0.077786847 | AD53: -0.0022138058
A54: 11 | B54: dLevel_T2_11 | C54: T2: Deals sites / price comparison websites | D54: -0.57013471 | E54: 0.026951927 | F54: 0.2670212 | G54: 0.28140898 | H54: 0.29875478 | I54: -0.19856767 | J54: -0.14453595 | K54: -0.016705462 | L54: -0.080703414 | M54: -0.1310309 | N54: -0.24211159 | O54: 0.038684878 | P54: -0.11494336 | Q54: 0.011676241 | R54: -0.23434315 | S54: -0.019181428 | T54: 0.20433803 | U54: 0.06479001 | V54: 0.032205244 | W54: -0.20609252 | X54: -0.10434327 | Y54: 0.31119817 | Z54: -0.10643684 | AA54: 0.10942576 | AB54: -0.008681374 | AC54: 0.0087918307 | AD54: -0.028203502
A55: 12 | B55: dLevel_T2_12 | C55: T2: Second-hand or rental websites | D55: -0.40503878 | E55: 0.36411591 | F55: 0.23055601 | G55: -0.13937649 | H55: -0.10419243 | I55: -0.30130975 | J55: -0.18726964 | K55: 0.02240598 | L55: -0.0058703462 | M55: 0.37949092 | N55: -0.049136872 | O55: -0.15439858 | P55: -0.087340831 | Q55: 0.085432426 | R55: 0.47412536 | S55: -0.14929849 | T55: -7.1497722e-05 | U55: -0.098439511 | V55: 0.071497368 | W55: -0.0044594979 | X55: -0.19691049 | Y55: 0.029960941 | Z55: -0.019156763 | AA55: 0.059193887 | AB55: -0.044268259 | AC55: -0.022738739 | AD55: 0.020283486
... A70: 27 | B70: dLevel_T2_28 | C70: T2: Recommendations from professional landscapers or garden contractors | D70: -0.50946207 | E70: -0.031055656 | F70: 0.26852758 | G70: 0.31236286 | H70: 0.20451621 | I70: 0.051800114 | J70: 0.2800381 | K70: -0.2422556 | L70: 0.086091602 | M70: 0.21262747 | N70: -0.065324934 | O70: 0.1651764 | P70: -0.21613313 | Q70: 0.038700382 | R70: -0.05868069 | S70: 0.015578126 | T70: -0.25137148 | U70: -0.26150157 | V70: -0.30489849 | W70: -0.0079649348 | X70: -0.054771802 | Y70: -0.14030287 | Z70: 0.034248772 | AA70: -0.023739355 | AB70: 0.014107571 | AC70: -0.019865264 | AD70: 0.05004681
A72: Rotated Component Matrix
A73: Rotation Method: Procrustes with Kaiser Normalization.
A75: VariableID | B75: Variable | C75: Lable | D75: Factor1 | E75: Factor2 | F75: Factor3 | G75: Factor4 | H75: Factor5 | I75: Factor6 | J75: Factor7 | K75: Factor8 | L75: Factor9 | M75: Factor10 | N75: Factor11 | O75: Factor12 | P75: Factor13 | Q75: Factor14 | R75: Factor15 | S75: Factor16 | T75: Factor17 | U75: Factor18 | V75: Factor19 | W75: Factor20 | X75: Factor21 | Y75: Factor22 | Z75: Factor23 | AA75: Factor24 | AB75: Factor25 | AC75: Factor26 | AD75: Factor27
...

Sheet 2C 均值
A1: Original KPIs
A2: Variable | B2: N | C2: Min | D2: Max | E2: Mean | F2: Std
A3: Level_ABA | B3: 1392 | C3: 0 | D3: 1 | E3: 0.99425287 | F3: 0.075618813
A4: Level_B6_T2B | B4: 1392 | C4: 0 | D4: 1 | E4: 0.77442529 | F4: 0.41811045
A5: Level_B7_T2B | B5: 1392 | C5: 0 | D5: 1 | E5: 0.72413793 | F5: 0.44710826
A6: Level_B4 | B6: 2400 | C6: 0 | D6: 1 | E6: 0.12 | F6: 0.32502926
A7: Level_B3a_T2B | B7: 1384 | C7: 0 | D7: 1 | E7: 0.79696532 | F7: 0.40240353
A8: Level_B11_T2B | B8: 1392 | C8: 0 | D8: 1 | E8: 0.50862069 | F8: 0.50010535
A9: Valid N (listwise) | B9: 699
A11: Recoded KPIs
A12: Variable | B12: N | C12: Min | D12: Max | E12: Mean | F12: Std
A13: dLevel_ABA | B13: 5320 | C13: 0 | D13: 1 | E13: 0.26015038 | F13: 0.43875773
A14: dLevel_B6_T2B | B14: 5320 | C14: 0 | D14: 1 | E14: 0.20263158 | F14: 0.40199801
A15: dLevel_B7_T2B | B15: 5320 | C15: 0 | D15: 1 | E15: 0.18947368 | F15: 0.39192127
A16: dLevel_B4 | B16: 5320 | C16: 0 | D16: 1 | E16: 0.054135338 | F16: 0.22630583
A17: dLevel_B3a_T2B | B17: 5320 | C17: 0 | D17: 1 | E17: 0.20733083 | F17: 0.40543267
A18: dLevel_B11_T2B | B18: 5320 | C18: 0 | D18: 1 | E18: 0.13308271 | F18: 0.33969603
A19: Valid N (listwise) | B19: 5320
A21: Original Channels
A22: Variable | B22: N | C22: Min | D22: Max | E22: Mean | F22: Std
A23: Level_T2_1 | B23: 920 | C23: 0 | D23: 1 | E23: 0.36086957 | F23: 0.48051399
A24: Level_T2_2 | B24: 920 | C24: 0 | D24: 1 | E24: 0.18478261 | F24: 0.38833222
A25: Level_T2_3 | B25: 920 | C25: 0 | D25: 1 | E25: 0.14130435 | F25: 0.34852469
A26: Level_T2_4 | B26: 920 | C26: 0 | D26: 1 | E26: 0.43586957 | F26: 0.49613995
A27: Level_T2_5 | B27: 920 | C27: 0 | D27: 1 | E27: 0.19782609 | F27: 0.39857697
A28: Level_T2_6 | B28: 920 | C28: 0 | D28: 1 | E28: 0.18478261 | F28: 0.38833222
A29: Level_T2_7 | B29: 920 | C29: 0 | D29: 1 | E29: 0.41413043 | F29: 0.49283915
A30: Level_T2_8 | B30: 920 | C30: 0 | D30: 1 | E30: 0.39021739 | F30: 0.48806424
A31: Level_T2_9 | B31: 920 | C31: 0 | D31: 1 | E31: 0.11195652 | F31: 0.31548446
A32: Level_T2_10 | B32: 920 | C32: 0 | D32: 1 | E32: 0.12608696 | F32: 0.33212789
A33: Level_T2_11 | B33: 920 | C33: 0 | D33: 1 | E33: 0.20978261 | F33: 0.40737483
A34: Level_T2_12 | B34: 920 | C34: 0 | D34: 1 | E34: 0.094565217 | F34: 0.29277262
... A49: Level_T2_28 | B49: 920 | C49: 0 | D49: 1 | E49: 0.15869565 | F49: 0.36559078
A50: Valid N (listwise) | B50: 920
A52: Recoded Channels
A53: Variable | B53: N | C53: Min | D53: Max | E53: Mean | F53: Std
A54: dLevel_T2_1 | B54: 5320 | C54: 0 | D54: 1 | E54: 0.062406015 | F54: 0.24191425
A55: dLevel_T2_2 | B55: 5320 | C55: 0 | D55: 1 | E55: 0.031954887 | F55: 0.17589653
A56: dLevel_T2_3 | B56: 5320 | C56: 0 | D56: 1 | E56: 0.02443609 | F56: 0.15441324
A57: dLevel_T2_4 | B57: 5320 | C57: 0 | D57: 1 | E57: 0.07537594 | F57: 0.2640218
...

Sheet 2D Mapping
A1: 2A Regression结果Table中对应的不同KPI | D1: 手写 | G1: ind Variable | H1: 变量名称
A2: 第几个table | B2: Dependent Variable | C2: 模型Base | D2: 变量名称 | G2: dLevel_T2_1 | H2: T2_1
A3: 1 | B3: {=IF($A3="","",_xlfn.LET( _xlpm.n,$A3, _xlpm.allRows,'2A Regression'!$A:$A, _xlpm.matches,IF(LEFT(_xlpm.allRows,19)="Dependent Variable:",ROW(_xlpm.allRows),""), _xlpm.nthRow,SMALL(IF(_xlpm.matches<>"",_xlpm.matches),_xlpm.n), _xlpm.result,INDEX(_xlpm.allRows,_xlpm.nthRow), IFERROR(SUBSTITUTE(_xlpm.result,"Dependent Variable: ",""),"") ))} -> dLevel_ABA | C3: Total | D3: ABA | G3: dLevel_T2_2 | H3: T2_2
A4: 2 | B4: {=IF($A4="","",_xlfn.LET( _xlpm.n,$A4, _xlpm.allRows,'2A Regression'!$A:$A, _xlpm.matches,IF(LEFT(_xlpm.allRows,19)="Dependent Variable:",ROW(_xlpm.allRows),""), _xlpm.nthRow,SMALL(IF(_xlpm.matches<>"",_xlpm.matches),_xlpm.n), _xlpm.result,INDEX(_xlpm.allRows,_xlpm.nthRow), IFERROR(SUBSTITUTE(_xlpm.result,"Dependent Variable: ",""),"") ))} -> dLevel_B6_T2B | C4: Total | D4: B6 | G4: dLevel_T2_3 | H4: T2_3
A5: 3 | B5: {=IF($A5="","",_xlfn.LET( _xlpm.n,$A5, _xlpm.allRows,'2A Regression'!$A:$A, _xlpm.matches,IF(LEFT(_xlpm.allRows,19)="Dependent Variable:",ROW(_xlpm.allRows),""), _xlpm.nthRow,SMALL(IF(_xlpm.matches<>"",_xlpm.matches),_xlpm.n), _xlpm.result,INDEX(_xlpm.allRows,_xlpm.nthRow), IFERROR(SUBSTITUTE(_xlpm.result,"Dependent Variable: ",""),"") ))} -> dLevel_ABA | C5: Total | D5: ABA1 | G5: dLevel_T2_4 | H5: T2_4
A6: 4 | B6: {=IF($A6="","",_xlfn.LET( _xlpm.n,$A6, _xlpm.allRows,'2A Regression'!$A:$A, _xlpm.matches,IF(LEFT(_xlpm.allRows,19)="Dependent Variable:",ROW(_xlpm.allRows),""), _xlpm.nthRow,SMALL(IF(_xlpm.matches<>"",_xlpm.matches),_xlpm.n), _xlpm.result,INDEX(_xlpm.allRows,_xlpm.nthRow), IFERROR(SUBSTITUTE(_xlpm.result,"Dependent Variable: ",""),"") ))} -> dLevel_B6_T2B | C6: Total | D6: B61 | G6: dLevel_T2_5 | H6: T2_5
A7: 5 | B7: {=IF($A7="","",_xlfn.LET( _xlpm.n,$A7, _xlpm.allRows,'2A Regression'!$A:$A, _xlpm.matches,IF(LEFT(_xlpm.allRows,19)="Dependent Variable:",ROW(_xlpm.allRows),""), _xlpm.nthRow,SMALL(IF(_xlpm.matches<>"",_xlpm.matches),_xlpm.n), _xlpm.result,INDEX(_xlpm.allRows,_xlpm.nthRow), IFERROR(SUBSTITUTE(_xlpm.result,"Dependent Variable: ",""),"") ))} -> dLevel_B7_T2B | C7: Total | D7: B7 | G7: dLevel_T2_6 | H7: T2_6
A8: 6 | B8: {=IF($A8="","",_xlfn.LET( _xlpm.n,$A8, _xlpm.allRows,'2A Regression'!$A:$A, _xlpm.matches,IF(LEFT(_xlpm.allRows,19)="Dependent Variable:",ROW(_xlpm.allRows),""), _xlpm.nthRow,SMALL(IF(_xlpm.matches<>"",_xlpm.matches),_xlpm.n), _xlpm.result,INDEX(_xlpm.allRows,_xlpm.nthRow), IFERROR(SUBSTITUTE(_xlpm.result,"Dependent Variable: ",""),"") ))} | C8: Total | G8: dLevel_T2_7 | H8: T2_7
A9: 7 | B9: {=IF($A9="","",_xlfn.LET( _xlpm.n,$A9, _xlpm.allRows,'2A Regression'!$A:$A, _xlpm.matches,IF(LEFT(_xlpm.allRows,19)="Dependent Variable:",ROW(_xlpm.allRows),""), _xlpm.nthRow,SMALL(IF(_xlpm.matches<>"",_xlpm.matches),_xlpm.n), _xlpm.result,INDEX(_xlpm.allRows,_xlpm.nthRow), IFERROR(SUBSTITUTE(_xlpm.result,"Dependent Variable: ",""),"") ))} | C9: Total | G9: dLevel_T2_8 | H9: T2_8
A10: 8 | B10: {=IF($A10="","",_xlfn.LET( _xlpm.n,$A10, _xlpm.allRows,'2A Regression'!$A:$A, _xlpm.matches,IF(LEFT(_xlpm.allRows,19)="Dependent Variable:",ROW(_xlpm.allRows),""), _xlpm.nthRow,SMALL(IF(_xlpm.matches<>"",_xlpm.matches),_xlpm.n), _xlpm.result,INDEX(_xlpm.allRows,_xlpm.nthRow), IFERROR(SUBSTITUTE(_xlpm.result,"Dependent Variable: ",""),"") ))} | C10: Total | G10: dLevel_T2_9 | H10: T2_9
A11: 9 | B11: {=IF($A11="","",_xlfn.LET( _xlpm.n,$A11, _xlpm.allRows,'2A Regression'!$A:$A, _xlpm.matches,IF(LEFT(_xlpm.allRows,19)="Dependent Variable:",ROW(_xlpm.allRows),""), _xlpm.nthRow,SMALL(IF(_xlpm.matches<>"",_xlpm.matches),_xlpm.n), _xlpm.result,INDEX(_xlpm.allRows,_xlpm.nthRow), IFERROR(SUBSTITUTE(_xlpm.result,"Dependent Variable: ",""),"") ))} | G11: dLevel_T2_10 | H11: T2_10
A12: 10 | B12: {=IF($A12="","",_xlfn.LET( _xlpm.n,$A12, _xlpm.allRows,'2A Regression'!$A:$A, _xlpm.matches,IF(LEFT(_xlpm.allRows,19)="Dependent Variable:",ROW(_xlpm.allRows),""), _xlpm.nthRow,SMALL(IF(_xlpm.matches<>"",_xlpm.matches),_xlpm.n), _xlpm.result,INDEX(_xlpm.allRows,_xlpm.nthRow), IFERROR(SUBSTITUTE(_xlpm.result,"Dependent Variable: ",""),"") ))} | G12: dLevel_T2_11 | H12: T2_11
A13: 11 | B13: {=IF($A13="","",_xlfn.LET( _xlpm.n,$A13, _xlpm.allRows,'2A Regression'!$A:$A, _xlpm.matches,IF(LEFT(_xlpm.allRows,19)="Dependent Variable:",ROW(_xlpm.allRows),""), _xlpm.nthRow,SMALL(IF(_xlpm.matches<>"",_xlpm.matches),_xlpm.n), _xlpm.result,INDEX(_xlpm.allRows,_xlpm.nthRow), IFERROR(SUBSTITUTE(_xlpm.result,"Dependent Variable: ",""),"") ))} | G13: dLevel_T2_12 | H13: T2_12
A14: 12 | B14: {=IF($A14="","",_xlfn.LET( _xlpm.n,$A14, _xlpm.allRows,'2A Regression'!$A:$A, _xlpm.matches,IF(LEFT(_xlpm.allRows,19)="Dependent Variable:",ROW(_xlpm.allRows),""), _xlpm.nthRow,SMALL(IF(_xlpm.matches<>"",_xlpm.matches),_xlpm.n), _xlpm.result,INDEX(_xlpm.allRows,_xlpm.nthRow), IFERROR(SUBSTITUTE(_xlpm.result,"Dependent Variable: ",""),"") ))} | G14: dLevel_T2_13 | H14: T2_13
A15: 13 | B15: {=IF($A15="","",_xlfn.LET( _xlpm.n,$A15, _xlpm.allRows,'2A Regression'!$A:$A, _xlpm.matches,IF(LEFT(_xlpm.allRows,19)="Dependent Variable:",ROW(_xlpm.allRows),""), _xlpm.nthRow,SMALL(IF(_xlpm.matches<>"",_xlpm.matches),_xlpm.n), _xlpm.result,INDEX(_xlpm.allRows,_xlpm.nthRow), IFERROR(SUBSTITUTE(_xlpm.result,"Dependent Variable: ",""),"") ))} | G15: dLevel_T2_14 | H15: T2_14
A16: 14 | B16: {=IF($A16="","",_xlfn.LET( _xlpm.n,$A16, _xlpm.allRows,'2A Regression'!$A:$A, _xlpm.matches,IF(LEFT(_xlpm.allRows,19)="Dependent Variable:",ROW(_xlpm.allRows),""), _xlpm.nthRow,SMALL(IF(_xlpm.matches<>"",_xlpm.matches),_xlpm.n), _xlpm.result,INDEX(_xlpm.allRows,_xlpm.nthRow), IFERROR(SUBSTITUTE(_xlpm.result,"Dependent Variable: ",""),"") ))} | G16: dLevel_T2_15 | H16: T2_15
A17: 15 | B17: {=IF($A17="","",_xlfn.LET( _xlpm.n,$A17, _xlpm.allRows,'2A Regression'!$A:$A, _xlpm.matches,IF(LEFT(_xlpm.allRows,19)="Dependent Variable:",ROW(_xlpm.allRows),""), _xlpm.nthRow,SMALL(IF(_xlpm.matches<>"",_xlpm.matches),_xlpm.n), _xlpm.result,INDEX(_xlpm.allRows,_xlpm.nthRow), IFERROR(SUBSTITUTE(_xlpm.result,"Dependent Variable: ",""),"") ))} | G17: dLevel_T2_16 | H17: T2_16
A18: 16 | B18: {=IF($A18="","",_xlfn.LET( _xlpm.n,$A18, _xlpm.allRows,'2A Regression'!$A:$A, _xlpm.matches,IF(LEFT(_xlpm.allRows,19)="Dependent Variable:",ROW(_xlpm.allRows),""), _xlpm.nthRow,SMALL(IF(_xlpm.matches<>"",_xlpm.matches),_xlpm.n), _xlpm.result,INDEX(_xlpm.allRows,_xlpm.nthRow), IFERROR(SUBSTITUTE(_xlpm.result,"Dependent Variable: ",""),"") ))} | G18: dLevel_T2_17 | H18: T2_17
A19: 17 | B19: {=IF($A19="","",_xlfn.LET( _xlpm.n,$A19, _xlpm.allRows,'2A Regression'!$A:$A, _xlpm.matches,IF(LEFT(_xlpm.allRows,19)="Dependent Variable:",ROW(_xlpm.allRows),""), _xlpm.nthRow,SMALL(IF(_xlpm.matches<>"",_xlpm.matches),_xlpm.n), _xlpm.result,INDEX(_xlpm.allRows,_xlpm.nthRow), IFERROR(SUBSTITUTE(_xlpm.result,"Dependent Variable: ",""),"") ))} | G19: dLevel_T2_18 | H19: T2_18
A20: 18 | B20: {=IF($A20="","",_xlfn.LET( _xlpm.n,$A20, _xlpm.allRows,'2A Regression'!$A:$A, _xlpm.matches,IF(LEFT(_xlpm.allRows,19)="Dependent Variable:",ROW(_xlpm.allRows),""), _xlpm.nthRow,SMALL(IF(_xlpm.matches<>"",_xlpm.matches),_xlpm.n), _xlpm.result,INDEX(_xlpm.allRows,_xlpm.nthRow), IFERROR(SUBSTITUTE(_xlpm.result,"Dependent Variable: ",""),"") ))} | G20: dLevel_T2_19 | H20: T2_19
A21: 19 | B21: {=IF($A21="","",_xlfn.LET( _xlpm.n,$A21, _xlpm.allRows,'2A Regression'!$A:$A, _xlpm.matches,IF(LEFT(_xlpm.allRows,19)="Dependent Variable:",ROW(_xlpm.allRows),""), _xlpm.nthRow,SMALL(IF(_xlpm.matches<>"",_xlpm.matches),_xlpm.n), _xlpm.result,INDEX(_xlpm.allRows,_xlpm.nthRow), IFERROR(SUBSTITUTE(_xlpm.result,"Dependent Variable: ",""),"") ))} | G21: dLevel_T2_21 | H21: T2_20
A22: 20 | B22: {=IF($A22="","",_xlfn.LET( _xlpm.n,$A22, _xlpm.allRows,'2A Regression'!$A:$A, _xlpm.matches,IF(LEFT(_xlpm.allRows,19)="Dependent Variable:",ROW(_xlpm.allRows),""), _xlpm.nthRow,SMALL(IF(_xlpm.matches<>"",_xlpm.matches),_xlpm.n), _xlpm.result,INDEX(_xlpm.allRows,_xlpm.nthRow), IFERROR(SUBSTITUTE(_xlpm.result,"Dependent Variable: ",""),"") ))} | G22: dLevel_T2_22 | H22: T2_21
G23: dLevel_T2_23 | H23: T2_22
G24: dLevel_T2_24 | H24: T2_23
G25: dLevel_T2_25 | H25: T2_24
G26: dLevel_T2_26 | H26: T2_25
G27: dLevel_T2_27 | H27: T2_26
G28: dLevel_T2_28 | H28: T2_27

Sheet 2E.Analysis_MIA
D1: 模型Base的样本 | E1: {=TRANSPOSE('2D Mapping'!C3:C22)} -> Total | F1: Total | G1: Total | H1: Total | I1: Total | J1: Total | K1: Total | L1: Total | M1: 0 | N1: 0 | O1: 0 | P1: 0 | Q1: 0 | R1: 0 | S1: 0 | T1: 0 | U1: 0 | V1: 0 | W1: 0 | X1: 0
A2: >>请输入： | D2: 标准化系数（回归模型结果） | E2: {=TRANSPOSE('2D Mapping'!B3:B22)} -> dLevel_ABA | F2: dLevel_B6_T2B | G2: dLevel_ABA | H2: dLevel_B6_T2B | I2: dLevel_B7_T2B
D3: Factor1 | E3: {=_xlfn.LET( _xlpm.kpiName, E$2, _xlpm.factorName, $D3, _xlpm.headerText, "Dependent Variable: "&_xlpm.kpiName, _xlpm.regA, '2A Regression'!$A$1:$A$10000, _xlpm.regB, '2A Regression'!$B$1:$B$10000, _xlpm.regE, '2A Regression'!$E$1:$E$10000, _xlpm.headerRow, MATCH(_xlpm.headerText, _xlpm.regA, 0), _xlpm.nextHeaderRow, _xlfn.AGGREGATE(15, 6, ROW(_xlpm.regA)/((LEFT(_xlpm.regA,19)="Dependent Variable:")*(ROW(_xlpm.regA)>_xlpm.headerRow)), 1), _xlpm.searchStart, _xlpm.headerRow, _xlpm.searchEnd, IF(ISERROR(_xlpm.nextHeaderRow), 300, _xlpm.nextHeaderRow-1), _xlpm.factorPos, _xlfn.AGGREGATE(15, 6, ROW(_xlpm.regB)/((_xlpm.regB=_xlpm.factorName)*(ROW(_xlpm.regB)>=_xlpm.searchStart)*(ROW(_xlpm.regB)<=_xlpm.searchEnd)), 1), IF(ISERROR(_xlpm.factorPos), 0, INDEX(_xlpm.regE, _xlpm.factorPos)) )} -> 0.039697503 | F3: {=_xlfn.LET( _xlpm.kpiName, F$2, _xlpm.factorName, $D3, _xlpm.headerText, "Dependent Variable: "&_xlpm.kpiName, _xlpm.regA, '2A Regression'!$A$1:$A$10000, _xlpm.regB, '2A Regression'!$B$1:$B$10000, _xlpm.regE, '2A Regression'!$E$1:$E$10000, _xlpm.headerRow, MATCH(_xlpm.headerText, _xlpm.regA, 0), _xlpm.nextHeaderRow, _xlfn.AGGREGATE(15, 6, ROW(_xlpm.regA)/((LEFT(_xlpm.regA,19)="Dependent Variable:")*(ROW(_xlpm.regA)>_xlpm.headerRow)), 1), _xlpm.searchStart, _xlpm.headerRow, _xlpm.searchEnd, IF(ISERROR(_xlpm.nextHeaderRow), 300, _xlpm.nextHeaderRow-1), _xlpm.factorPos, _xlfn.AGGREGATE(15, 6, ROW(_xlpm.regB)/((_xlpm.regB=_xlpm.factorName)*(ROW(_xlpm.regB)>=_xlpm.searchStart)*(ROW(_xlpm.regB)<=_xlpm.searchEnd)), 1), IF(ISERROR(_xlpm.factorPos), 0, INDEX(_xlpm.regE, _xlpm.factorPos)) )} -> 0.042726247 | G3: {=_xlfn.LET( _xlpm.kpiName, G$2, _xlpm.factorName, $D3, _xlpm.headerText, "Dependent Variable: "&_xlpm.kpiName, _xlpm.regA, '2A Regression'!$A$1:$A$10000, _xlpm.regB, '2A Regression'!$B$1:$B$10000, _xlpm.regE, '2A Regression'!$E$1:$E$10000, _xlpm.headerRow, MATCH(_xlpm.headerText, _xlpm.regA, 0), _xlpm.nextHeaderRow, _xlfn.AGGREGATE(15, 6, ROW(_xlpm.regA)/((LEFT(_xlpm.regA,19)="Dependent Variable:")*(ROW(_xlpm.regA)>_xlpm.headerRow)), 1), _xlpm.searchStart, _xlpm.headerRow, _xlpm.searchEnd, IF(ISERROR(_xlpm.nextHeaderRow), 300, _xlpm.nextHeaderRow-1), _xlpm.factorPos, _xlfn.AGGREGATE(15, 6, ROW(_xlpm.regB)/((_xlpm.regB=_xlpm.factorName)*(ROW(_xlpm.regB)>=_xlpm.searchStart)*(ROW(_xlpm.regB)<=_xlpm.searchEnd)), 1), IF(ISERROR(_xlpm.factorPos), 0, INDEX(_xlpm.regE, _xlpm.factorPos)) )} -> 0.039697503 | H3: {=_xlfn.LET( _xlpm.kpiName, H$2, _xlpm.factorName, $D3, _xlpm.headerText, "Dependent Variable: "&_xlpm.kpiName, _xlpm.regA, '2A Regression'!$A$1:$A$10000, _xlpm.regB, '2A Regression'!$B$1:$B$10000, _xlpm.regE, '2A Regression'!$E$1:$E$10000, _xlpm.headerRow, MATCH(_xlpm.headerText, _xlpm.regA, 0), _xlpm.nextHeaderRow, _xlfn.AGGREGATE(15, 6, ROW(_xlpm.regA)/((LEFT(_xlpm.regA,19)="Dependent Variable:")*(ROW(_xlpm.regA)>_xlpm.headerRow)), 1), _xlpm.searchStart, _xlpm.headerRow, _xlpm.searchEnd, IF(ISERROR(_xlpm.nextHeaderRow), 300, _xlpm.nextHeaderRow-1), _xlpm.factorPos, _xlfn.AGGREGATE(15, 6, ROW(_xlpm.regB)/((_xlpm.regB=_xlpm.factorName)*(ROW(_xlpm.regB)>=_xlpm.searchStart)*(ROW(_xlpm.regB)<=_xlpm.searchEnd)), 1), IF(ISERROR(_xlpm.factorPos), 0, INDEX(_xlpm.regE, _xlpm.factorPos)) )} -> 0.042726247 | I3: {=_xlfn.LET( _xlpm.kpiName, I$2, _xlpm.factorName, $D3, _xlpm.headerText, "Dependent Variable: "&_xlpm.kpiName, _xlpm.regA, '2A Regression'!$A$1:$A$10000, _xlpm.regB, '2A Regression'!$B$1:$B$10000, _xlpm.regE, '2A Regression'!$E$1:$E$10000, _xlpm.headerRow, MATCH(_xlpm.headerText, _xlpm.regA, 0), _xlpm.nextHeaderRow, _xlfn.AGGREGATE(15, 6, ROW(_xlpm.regA)/((LEFT(_xlpm.regA,19)="Dependent Variable:")*(ROW(_xlpm.regA)>_xlpm.headerRow)), 1), _xlpm.searchStart, _xlpm.headerRow, _xlpm.searchEnd, IF(ISERROR(_xlpm.nextHeaderRow), 300, _xlpm.nextHeaderRow-1), _xlpm.factorPos, _xlfn.AGGREGATE(15, 6, ROW(_xlpm.regB)/((_xlpm.regB=_xlpm.factorName)*(ROW(_xlpm.regB)>=_xlpm.searchStart)*(ROW(_xlpm.regB)<=_xlpm.searchEnd)), 1), IF(ISERROR(_xlpm.factorPos), 0, INDEX(_xlpm.regE, _xlpm.factorPos)) )} -> 0.18742168 | J3: {=_xlfn.LET( _xlpm.kpiName, J$2, _xlpm.factorName, $D3, _xlpm.headerText, "Dependent Variable: "&_xlpm.kpiName, _xlpm.regA, '2A Regression'!$A$1:$A$10000, _xlpm.regB, '2A Regression'!$B$1:$B$10000, _xlpm.regE, '2A Regression'!$E$1:$E$10000, _xlpm.headerRow, MATCH(_xlpm.headerText, _xlpm.regA, 0), _xlpm.nextHeaderRow, _xlfn.AGGREGATE(15, 6, ROW(_xlpm.regA)/((LEFT(_xlpm.regA,19)="Dependent Variable:")*(ROW(_xlpm.regA)>_xlpm.headerRow)), 1), _xlpm.searchStart, _xlpm.headerRow, _xlpm.searchEnd, IF(ISERROR(_xlpm.nextHeaderRow), 300, _xlpm.nextHeaderRow-1), _xlpm.factorPos, _xlfn.AGGREGATE(15, 6, ROW(_xlpm.regB)/((_xlpm.regB=_xlpm.factorName)*(ROW(_xlpm.regB)>=_xlpm.searchStart)*(ROW(_xlpm.regB)<=_xlpm.searchEnd)), 1), IF(ISERROR(_xlpm.factorPos), 0, INDEX(_xlpm.regE, _xlpm.factorPos)) )} -> 0 | K3: {=_xlfn.LET( _xlpm.kpiName, K$2, _xlpm.factorName, $D3, _xlpm.headerText, "Dependent Variable: "&_xlpm.kpiName, _xlpm.regA, '2A Regression'!$A$1:$A$10000, _xlpm.regB, '2A Regression'!$B$1:$B$10000, _xlpm.regE, '2A Regression'!$E$1:$E$10000, _xlpm.headerRow, MATCH(_xlpm.headerText, _xlpm.regA, 0), _xlpm.nextHeaderRow, _xlfn.AGGREGATE(15, 6, ROW(_xlpm.regA)/((LEFT(_xlpm.regA,19)="Dependent Variable:")*(ROW(_xlpm.regA)>_xlpm.headerRow)), 1), _xlpm.searchStart, _xlpm.headerRow, _xlpm.searchEnd, IF(ISERROR(_xlpm.nextHeaderRow), 300, _xlpm.nextHeaderRow-1), _xlpm.factorPos, _xlfn.AGGREGATE(15, 6, ROW(_xlpm.regB)/((_xlpm.regB=_xlpm.factorName)*(ROW(_xlpm.regB)>=_xlpm.searchStart)*(ROW(_xlpm.regB)<=_xlpm.searchEnd)), 1), IF(ISERROR(_xlpm.factorPos), 0, INDEX(_xlpm.regE, _xlpm.factorPos)) )} -> 0 | L3: {=_xlfn.LET( _xlpm.kpiName, L$2, _xlpm.factorName, $D3, _xlpm.headerText, "Dependent Variable: "&_xlpm.kpiName, _xlpm.regA, '2A Regression'!$A$1:$A$10000, _xlpm.regB, '2A Regression'!$B$1:$B$10000, _xlpm.regE, '2A Regression'!$E$1:$E$10000, _xlpm.headerRow, MATCH(_xlpm.headerText, _xlpm.regA, 0), _xlpm.nextHeaderRow, _xlfn.AGGREGATE(15, 6, ROW(_xlpm.regA)/((LEFT(_xlpm.regA,19)="Dependent Variable:")*(ROW(_xlpm.regA)>_xlpm.headerRow)), 1), _xlpm.searchStart, _xlpm.headerRow, _xlpm.searchEnd, IF(ISERROR(_xlpm.nextHeaderRow), 300, _xlpm.nextHeaderRow-1), _xlpm.factorPos, _xlfn.AGGREGATE(15, 6, ROW(_xlpm.regB)/((_xlpm.regB=_xlpm.factorName)*(ROW(_xlpm.regB)>=_xlpm.searchStart)*(ROW(_xlpm.regB)<=_xlpm.searchEnd)), 1), IF(ISERROR(_xlpm.factorPos), 0, INDEX(_xlpm.regE, _xlpm.factorPos)) )} -> 0 | ... X3: {=_xlfn.LET( _xlpm.kpiName, X$2, _xlpm.factorName, $D3, _xlpm.headerText, "Dependent Variable: "&_xlpm.kpiName, _xlpm.regA, '2A Regression'!$A$1:$A$10000, _xlpm.regB, '2A Regression'!$B$1:$B$10000, _xlpm.regE, '2A Regression'!$E$1:$E$10000, _xlpm.headerRow, MATCH(_xlpm.headerText, _xlpm.regA, 0), _xlpm.nextHeaderRow, _xlfn.AGGREGATE(15, 6, ROW(_xlpm.regA)/((LEFT(_xlpm.regA,19)="Dependent Variable:")*(ROW(_xlpm.regA)>_xlpm.headerRow)), 1), _xlpm.searchStart, _xlpm.headerRow, _xlpm.searchEnd, IF(ISERROR(_xlpm.nextHeaderRow), 300, _xlpm.nextHeaderRow-1), _xlpm.factorPos, _xlfn.AGGREGATE(15, 6, ROW(_xlpm.regB)/((_xlpm.regB=_xlpm.factorName)*(ROW(_xlpm.regB)>=_xlpm.searchStart)*(ROW(_xlpm.regB)<=_xlpm.searchEnd)), 1), IF(ISERROR(_xlpm.factorPos), 0, INDEX(_xlpm.regE, _xlpm.factorPos)) )} -> 0
A4: 是否有brand dispo信息（Yes：1，No：0） | B4: 0 | D4: Factor2 | E4: {=_xlfn.LET( _xlpm.kpiName, E$2, _xlpm.factorName, $D4, _xlpm.headerText, "Dependent Variable: "&_xlpm.kpiName, _xlpm.regA, '2A Regression'!$A$1:$A$10000, _xlpm.regB, '2A Regression'!$B$1:$B$10000, _xlpm.regE, '2A Regression'!$E$1:$E$10000, _xlpm.headerRow, MATCH(_xlpm.headerText, _xlpm.regA, 0), _xlpm.nextHeaderRow, _xlfn.AGGREGATE(15, 6, ROW(_xlpm.regA)/((LEFT(_xlpm.regA,19)="Dependent Variable:")*(ROW(_xlpm.regA)>_xlpm.headerRow)), 1), _xlpm.searchStart, _xlpm.headerRow, _xlpm.searchEnd, IF(ISERROR(_xlpm.nextHeaderRow), 300, _xlpm.nextHeaderRow-1), _xlpm.factorPos, _xlfn.AGGREGATE(15, 6, ROW(_xlpm.regB)/((_xlpm.regB=_xlpm.factorName)*(ROW(_xlpm.regB)>=_xlpm.searchStart)*(ROW(_xlpm.regB)<=_xlpm.searchEnd)), 1), IF(ISERROR(_xlpm.factorPos), 0, INDEX(_xlpm.regE, _xlpm.factorPos)) )} -> 0.019051102 | F4: {=_xlfn.LET( _xlpm.kpiName, F$2, _xlpm.factorName, $D4, _xlpm.headerText, "Dependent Variable: "&_xlpm.kpiName, _xlpm.regA, '2A Regression'!$A$1:$A$10000, _xlpm.regB, '2A Regression'!$B$1:$B$10000, _xlpm.regE, '2A Regression'!$E$1:$E$10000, _xlpm.headerRow, MATCH(_xlpm.headerText, _xlpm.regA, 0), _xlpm.nextHeaderRow, _xlfn.AGGREGATE(15, 6, ROW(_xlpm.regA)/((LEFT(_xlpm.regA,19)="Dependent Variable:")*(ROW(_xlpm.regA)>_xlpm.headerRow)), 1), _xlpm.searchStart, _xlpm.headerRow, _xlpm.searchEnd, IF(ISERROR(_xlpm.nextHeaderRow), 300, _xlpm.nextHeaderRow-1), _xlpm.factorPos, _xlfn.AGGREGATE(15, 6, ROW(_xlpm.regB)/((_xlpm.regB=_xlpm.factorName)*(ROW(_xlpm.regB)>=_xlpm.searchStart)*(ROW(_xlpm.regB)<=_xlpm.searchEnd)), 1), IF(ISERROR(_xlpm.factorPos), 0, INDEX(_xlpm.regE, _xlpm.factorPos)) )} -> 0.0082534884 | G4: {=_xlfn.LET( _xlpm.kpiName, G$2, _xlpm.factorName, $D4, _xlpm.headerText, "Dependent Variable: "&_xlpm.kpiName, _xlpm.regA, '2A Regression'!$A$1:$A$10000, _xlpm.regB, '2A Regression'!$B$1:$B$10000, _xlpm.regE, '2A Regression'!$E$1:$E$10000, _xlpm.headerRow, MATCH(_xlpm.headerText, _xlpm.regA, 0), _xlpm.nextHeaderRow, _xlfn.AGGREGATE(15, 6, ROW(_xlpm.regA)/((LEFT(_xlpm.regA,19)="Dependent Variable:")*(ROW(_xlpm.regA)>_xlpm.headerRow)), 1), _xlpm.searchStart, _xlpm.headerRow, _xlpm.searchEnd, IF(ISERROR(_xlpm.nextHeaderRow), 300, _xlpm.nextHeaderRow-1), _xlpm.factorPos, _xlfn.AGGREGATE(15, 6, ROW(_xlpm.regB)/((_xlpm.regB=_xlpm.factorName)*(ROW(_xlpm.regB)>=_xlpm.searchStart)*(ROW(_xlpm.regB)<=_xlpm.searchEnd)), 1), IF(ISERROR(_xlpm.factorPos), 0, INDEX(_xlpm.regE, _xlpm.factorPos)) )} -> 0.019051102 | H4: {=_xlfn.LET( _xlpm.kpiName, H$2, _xlpm.factorName, $D4, _xlpm.headerText, "Dependent Variable: "&_xlpm.kpiName, _xlpm.regA, '2A Regression'!$A$1:$A$10000, _xlpm.regB, '2A Regression'!$B$1:$B$10000, _xlpm.regE, '2A Regression'!$E$1:$E$10000, _xlpm.headerRow, MATCH(_xlpm.headerText, _xlpm.regA, 0), _xlpm.nextHeaderRow, _xlfn.AGGREGATE(15, 6, ROW(_xlpm.regA)/((LEFT(_xlpm.regA,19)="Dependent Variable:")*(ROW(_xlpm.regA)>_xlpm.headerRow)), 1), _xlpm.searchStart, _xlpm.headerRow, _xlpm.searchEnd, IF(ISERROR(_xlpm.nextHeaderRow), 300, _xlpm.nextHeaderRow-1), _xlpm.factorPos, _xlfn.AGGREGATE(15, 6, ROW(_xlpm.regB)/((_xlpm.regB=_xlpm.factorName)*(ROW(_xlpm.regB)>=_xlpm.searchStart)*(ROW(_xlpm.regB)<=_xlpm.searchEnd)), 1), IF(ISERROR(_xlpm.factorPos), 0, INDEX(_xlpm.regE, _xlpm.factorPos)) )} -> 0.0082534884 | I4: {=_xlfn.LET( _xlpm.kpiName, I$2, _xlpm.factorName, $D4, _xlpm.headerText, "Dependent Variable: "&_xlpm.kpiName, _xlpm.regA, '2A Regression'!$A$1:$A$10000, _xlpm.regB, '2A Regression'!$B$1:$B$10000, _xlpm.regE, '2A Regression'!$E$1:$E$10000, _xlpm.headerRow, MATCH(_xlpm.headerText, _xlpm.regA, 0), _xlpm.nextHeaderRow, _xlfn.AGGREGATE(15, 6, ROW(_xlpm.regA)/((LEFT(_xlpm.regA,19)="Dependent Variable:")*(ROW(_xlpm.regA)>_xlpm.headerRow)), 1), _xlpm.searchStart, _xlpm.headerRow, _xlpm.searchEnd, IF(ISERROR(_xlpm.nextHeaderRow), 300, _xlpm.nextHeaderRow-1), _xlpm.factorPos, _xlfn.AGGREGATE(15, 6, ROW(_xlpm.regB)/((_xlpm.regB=_xlpm.factorName)*(ROW(_xlpm.regB)>=_xlpm.searchStart)*(ROW(_xlpm.regB)<=_xlpm.searchEnd)), 1), IF(ISERROR(_xlpm.factorPos), 0, INDEX(_xlpm.regE, _xlpm.factorPos)) )} -> 0.12980782 | J4: {=_xlfn.LET( _xlpm.kpiName, J$2, _xlpm.factorName, $D4, _xlpm.headerText, "Dependent Variable: "&_xlpm.kpiName, _xlpm.regA, '2A Regression'!$A$1:$A$10000, _xlpm.regB, '2A Regression'!$B$1:$B$10000, _xlpm.regE, '2A Regression'!$E$1:$E$10000, _xlpm.headerRow, MATCH(_xlpm.headerText, _xlpm.regA, 0), _xlpm.nextHeaderRow, _xlfn.AGGREGATE(15, 6, ROW(_xlpm.regA)/((LEFT(_xlpm.regA,19)="Dependent Variable:")*(ROW(_xlpm.regA)>_xlpm.headerRow)), 1), _xlpm.searchStart, _xlpm.headerRow, _xlpm.searchEnd, IF(ISERROR(_xlpm.nextHeaderRow), 300, _xlpm.nextHeaderRow-1), _xlpm.factorPos, _xlfn.AGGREGATE(15, 6, ROW(_xlpm.regB)/((_xlpm.regB=_xlpm.factorName)*(ROW(_xlpm.regB)>=_xlpm.searchStart)*(ROW(_xlpm.regB)<=_xlpm.searchEnd)), 1), IF(ISERROR(_xlpm.factorPos), 0, INDEX(_xlpm.regE, _xlpm.factorPos)) )} -> 0 | K4: {=_xlfn.LET( _xlpm.kpiName, K$2, _xlpm.factorName, $D4, _xlpm.headerText, "Dependent Variable: "&_xlpm.kpiName, _xlpm.regA, '2A Regression'!$A$1:$A$10000, _xlpm.regB, '2A Regression'!$B$1:$B$10000, _xlpm.regE, '2A Regression'!$E$1:$E$10000, _xlpm.headerRow, MATCH(_xlpm.headerText, _xlpm.regA, 0), _xlpm.nextHeaderRow, _xlfn.AGGREGATE(15, 6, ROW(_xlpm.regA)/((LEFT(_xlpm.regA,19)="Dependent Variable:")*(ROW(_xlpm.regA)>_xlpm.headerRow)), 1), _xlpm.searchStart, _xlpm.headerRow, _xlpm.searchEnd, IF(ISERROR(_xlpm.nextHeaderRow), 300, _xlpm.nextHeaderRow-1), _xlpm.factorPos, _xlfn.AGGREGATE(15, 6, ROW(_xlpm.regB)/((_xlpm.regB=_xlpm.factorName)*(ROW(_xlpm.regB)>=_xlpm.searchStart)*(ROW(_xlpm.regB)<=_xlpm.searchEnd)), 1), IF(ISERROR(_xlpm.factorPos), 0, INDEX(_xlpm.regE, _xlpm.factorPos)) )} -> 0 | L4: {=_xlfn.LET( _xlpm.kpiName, L$2, _xlpm.factorName, $D4, _xlpm.headerText, "Dependent Variable: "&_xlpm.kpiName, _xlpm.regA, '2A Regression'!$A$1:$A$10000, _xlpm.regB, '2A Regression'!$B$1:$B$10000, _xlpm.regE, '2A Regression'!$E$1:$E$10000, _xlpm.headerRow, MATCH(_xlpm.headerText, _xlpm.regA, 0), _xlpm.nextHeaderRow, _xlfn.AGGREGATE(15, 6, ROW(_xlpm.regA)/((LEFT(_xlpm.regA,19)="Dependent Variable:")*(ROW(_xlpm.regA)>_xlpm.headerRow)), 1), _xlpm.searchStart, _xlpm.headerRow, _xlpm.searchEnd, IF(ISERROR(_xlpm.nextHeaderRow), 300, _xlpm.nextHeaderRow-1), _xlpm.factorPos, _xlfn.AGGREGATE(15, 6, ROW(_xlpm.regB)/((_xlpm.regB=_xlpm.factorName)*(ROW(_xlpm.regB)>=_xlpm.searchStart)*(ROW(_xlpm.regB)<=_xlpm.searchEnd)), 1), IF(ISERROR(_xlpm.factorPos), 0, INDEX(_xlpm.regE, _xlpm.factorPos)) )} -> 0 | ... X4: {=_xlfn.LET( _xlpm.kpiName, X$2, _xlpm.factorName, $D4, _xlpm.headerText, "Dependent Variable: "&_xlpm.kpiName, _xlpm.regA, '2A Regression'!$A$1:$A$10000, _xlpm.regB, '2A Regression'!$B$1:$B$10000, _xlpm.regE, '2A Regression'!$E$1:$E$10000, _xlpm.headerRow, MATCH(_xlpm.headerText, _xlpm.regA, 0), _xlpm.nextHeaderRow, _xlfn.AGGREGATE(15, 6, ROW(_xlpm.regA)/((LEFT(_xlpm.regA,19)="Dependent Variable:")*(ROW(_xlpm.regA)>_xlpm.headerRow)), 1), _xlpm.searchStart, _xlpm.headerRow, _xlpm.searchEnd, IF(ISERROR(_xlpm.nextHeaderRow), 300, _xlpm.nextHeaderRow-1), _xlpm.factorPos, _xlfn.AGGREGATE(15, 6, ROW(_xlpm.regB)/((_xlpm.regB=_xlpm.factorName)*(ROW(_xlpm.regB)>=_xlpm.searchStart)*(ROW(_xlpm.regB)<=_xlpm.searchEnd)), 1), IF(ISERROR(_xlpm.factorPos), 0, INDEX(_xlpm.regE, _xlpm.factorPos)) )} -> 0
D5: Factor3 | E5: {=_xlfn.LET( _xlpm.kpiName, E$2, _xlpm.factorName, $D5, _xlpm.headerText, "Dependent Variable: "&_xlpm.kpiName, _xlpm.regA, '2A Regression'!$A$1:$A$10000, _xlpm.regB, '2A Regression'!$B$1:$B$10000, _xlpm.regE, '2A Regression'!$E$1:$E$10000, _xlpm.headerRow, MATCH(_xlpm.headerText, _xlpm.regA, 0), _xlpm.nextHeaderRow, _xlfn.AGGREGATE(15, 6, ROW(_xlpm.regA)/((LEFT(_xlpm.regA,19)="Dependent Variable:")*(ROW(_xlpm.regA)>_xlpm.headerRow)), 1), _xlpm.searchStart, _xlpm.headerRow, _xlpm.searchEnd, IF(ISERROR(_xlpm.nextHeaderRow), 300, _xlpm.nextHeaderRow-1), _xlpm.factorPos, _xlfn.AGGREGATE(15, 6, ROW(_xlpm.regB)/((_xlpm.regB=_xlpm.factorName)*(ROW(_xlpm.regB)>=_xlpm.searchStart)*(ROW(_xlpm.regB)<=_xlpm.searchEnd)), 1), IF(ISERROR(_xlpm.factorPos), 0, INDEX(_xlpm.regE, _xlpm.factorPos)) )} -> 0.016392829 | F5: {=_xlfn.LET( _xlpm.kpiName, F$2, _xlpm.factorName, $D5, _xlpm.headerText, "Dependent Variable: "&_xlpm.kpiName, _xlpm.regA, '2A Regression'!$A$1:$A$10000, _xlpm.regB, '2A Regression'!$B$1:$B$10000, _xlpm.regE, '2A Regression'!$E$1:$E$10000, _xlpm.headerRow, MATCH(_xlpm.headerText, _xlpm.regA, 0), _xlpm.nextHeaderRow, _xlfn.AGGREGATE(15, 6, ROW(_xlpm.regA)/((LEFT(_xlpm.regA,19)="Dependent Variable:")*(ROW(_xlpm.regA)>_xlpm.headerRow)), 1), _xlpm.searchStart, _xlpm.headerRow, _xlpm.searchEnd, IF(ISERROR(_xlpm.nextHeaderRow), 300, _xlpm.nextHeaderRow-1), _xlpm.factorPos, _xlfn.AGGREGATE(15, 6, ROW(_xlpm.regB)/((_xlpm.regB=_xlpm.factorName)*(ROW(_xlpm.regB)>=_xlpm.searchStart)*(ROW(_xlpm.regB)<=_xlpm.searchEnd)), 1), IF(ISERROR(_xlpm.factorPos), 0, INDEX(_xlpm.regE, _xlpm.factorPos)) )} -> 0.0086612981 | G5: {=_xlfn.LET( _xlpm.kpiName, G$2, _xlpm.factorName, $D5, _xlpm.headerText, "Dependent Variable: "&_xlpm.kpiName, _xlpm.regA, '2A Regression'!$A$1:$A$10000, _xlpm.regB, '2A Regression'!$B$1:$B$10000, _xlpm.regE, '2A Regression'!$E$1:$E$10000, _xlpm.headerRow, MATCH(_xlpm.headerText, _xlpm.regA, 0), _xlpm.nextHeaderRow, _xlfn.AGGREGATE(15, 6, ROW(_xlpm.regA)/((LEFT(_xlpm.regA,19)="Dependent Variable:")*(ROW(_xlpm.regA)>_xlpm.headerRow)), 1), _xlpm.searchStart, _xlpm.headerRow, _xlpm.searchEnd, IF(ISERROR(_xlpm.nextHeaderRow), 300, _xlpm.nextHeaderRow-1), _xlpm.factorPos, _xlfn.AGGREGATE(15, 6, ROW(_xlpm.regB)/((_xlpm.regB=_xlpm.factorName)*(ROW(_xlpm.regB)>=_xlpm.searchStart)*(ROW(_xlpm.regB)<=_xlpm.searchEnd)), 1), IF(ISERROR(_xlpm.factorPos), 0, INDEX(_xlpm.regE, _xlpm.factorPos)) )} -> 0.016392829 | H5: {=_xlfn.LET( _xlpm.kpiName, H$2, _xlpm.factorName, $D5, _xlpm.headerText, "Dependent Variable: "&_xlpm.kpiName, _xlpm.regA, '2A Regression'!$A$1:$A$10000, _xlpm.regB, '2A Regression'!$B$1:$B$10000, _xlpm.regE, '2A Regression'!$E$1:$E$10000, _xlpm.headerRow, MATCH(_xlpm.headerText, _xlpm.regA, 0), _xlpm.nextHeaderRow, _xlfn.AGGREGATE(15, 6, ROW(_xlpm.regA)/((LEFT(_xlpm.regA,19)="Dependent Variable:")*(ROW(_xlpm.regA)>_xlpm.headerRow)), 1), _xlpm.searchStart, _xlpm.headerRow, _xlpm.searchEnd, IF(ISERROR(_xlpm.nextHeaderRow), 300, _xlpm.nextHeaderRow-1), _xlpm.factorPos, _xlfn.AGGREGATE(15, 6, ROW(_xlpm.regB)/((_xlpm.regB=_xlpm.factorName)*(ROW(_xlpm.regB)>=_xlpm.searchStart)*(ROW(_xlpm.regB)<=_xlpm.searchEnd)), 1), IF(ISERROR(_xlpm.factorPos), 0, INDEX(_xlpm.regE, _xlpm.factorPos)) )} -> 0.0086612981 | I5: {=_xlfn.LET( _xlpm.kpiName, I$2, _xlpm.factorName, $D5, _xlpm.headerText, "Dependent Variable: "&_xlpm.kpiName, _xlpm.regA, '2A Regression'!$A$1:$A$10000, _xlpm.regB, '2A Regression'!$B$1:$B$10000, _xlpm.regE, '2A Regression'!$E$1:$E$10000, _xlpm.headerRow, MATCH(_xlpm.headerText, _xlpm.regA, 0), _xlpm.nextHeaderRow, _xlfn.AGGREGATE(15, 6, ROW(_xlpm.regA)/((LEFT(_xlpm.regA,19)="Dependent Variable:")*(ROW(_xlpm.regA)>_xlpm.headerRow)), 1), _xlpm.searchStart, _xlpm.headerRow, _xlpm.searchEnd, IF(ISERROR(_xlpm.nextHeaderRow), 300, _xlpm.nextHeaderRow-1), _xlpm.factorPos, _xlfn.AGGREGATE(15, 6, ROW(_xlpm.regB)/((_xlpm.regB=_xlpm.factorName)*(ROW(_xlpm.regB)>=_xlpm.searchStart)*(ROW(_xlpm.regB)<=_xlpm.searchEnd)), 1), IF(ISERROR(_xlpm.factorPos), 0, INDEX(_xlpm.regE, _xlpm.factorPos)) )} -> 0.11539505 | J5: {=_xlfn.LET( _xlpm.kpiName, J$2, _xlpm.factorName, $D5, _xlpm.headerText, "Dependent Variable: "&_xlpm.kpiName, _xlpm.regA, '2A Regression'!$A$1:$A$10000, _xlpm.regB, '2A Regression'!$B$1:$B$10000, _xlpm.regE, '2A Regression'!$E$1:$E$10000, _xlpm.headerRow, MATCH(_xlpm.headerText, _xlpm.regA, 0), _xlpm.nextHeaderRow, _xlfn.AGGREGATE(15, 6, ROW(_xlpm.regA)/((LEFT(_xlpm.regA,19)="Dependent Variable:")*(ROW(_xlpm.regA)>_xlpm.headerRow)), 1), _xlpm.searchStart, _xlpm.headerRow, _xlpm.searchEnd, IF(ISERROR(_xlpm.nextHeaderRow), 300, _xlpm.nextHeaderRow-1), _xlpm.factorPos, _xlfn.AGGREGATE(15, 6, ROW(_xlpm.regB)/((_xlpm.regB=_xlpm.factorName)*(ROW(_xlpm.regB)>=_xlpm.searchStart)*(ROW(_xlpm.regB)<=_xlpm.searchEnd)), 1), IF(ISERROR(_xlpm.factorPos), 0, INDEX(_xlpm.regE, _xlpm.factorPos)) )} -> 0 | K5: {=_xlfn.LET( _xlpm.kpiName, K$2, _xlpm.factorName, $D5, _xlpm.headerText, "Dependent Variable: "&_xlpm.kpiName, _xlpm.regA, '2A Regression'!$A$1:$A$10000, _xlpm.regB, '2A Regression'!$B$1:$B$10000, _xlpm.regE, '2A Regression'!$E$1:$E$10000, _xlpm.headerRow, MATCH(_xlpm.headerText, _xlpm.regA, 0), _xlpm.nextHeaderRow, _xlfn.AGGREGATE(15, 6, ROW(_xlpm.regA)/((LEFT(_xlpm.regA,19)="Dependent Variable:")*(ROW(_xlpm.regA)>_xlpm.headerRow)), 1), _xlpm.searchStart, _xlpm.headerRow, _xlpm.searchEnd, IF(ISERROR(_xlpm.nextHeaderRow), 300, _xlpm.nextHeaderRow-1), _xlpm.factorPos, _xlfn.AGGREGATE(15, 6, ROW(_xlpm.regB)/((_xlpm.regB=_xlpm.factorName)*(ROW(_xlpm.regB)>=_xlpm.searchStart)*(ROW(_xlpm.regB)<=_xlpm.searchEnd)), 1), IF(ISERROR(_xlpm.factorPos), 0, INDEX(_xlpm.regE, _xlpm.factorPos)) )} -> 0 | L5: {=_xlfn.LET( _xlpm.kpiName, L$2, _xlpm.factorName, $D5, _xlpm.headerText, "Dependent Variable: "&_xlpm.kpiName, _xlpm.regA, '2A Regression'!$A$1:$A$10000, _xlpm.regB, '2A Regression'!$B$1:$B$10000, _xlpm.regE, '2A Regression'!$E$1:$E$10000, _xlpm.headerRow, MATCH(_xlpm.headerText, _xlpm.regA, 0), _xlpm.nextHeaderRow, _xlfn.AGGREGATE(15, 6, ROW(_xlpm.regA)/((LEFT(_xlpm.regA,19)="Dependent Variable:")*(ROW(_xlpm.regA)>_xlpm.headerRow)), 1), _xlpm.searchStart, _xlpm.headerRow, _xlpm.searchEnd, IF(ISERROR(_xlpm.nextHeaderRow), 300, _xlpm.nextHeaderRow-1), _xlpm.factorPos, _xlfn.AGGREGATE(15, 6, ROW(_xlpm.regB)/((_xlpm.regB=_xlpm.factorName)*(ROW(_xlpm.regB)>=_xlpm.searchStart)*(ROW(_xlpm.regB)<=_xlpm.searchEnd)), 1), IF(ISERROR(_xlpm.factorPos), 0, INDEX(_xlpm.regE, _xlpm.factorPos)) )} -> 0 | ... X5: {=_xlfn.LET( _xlpm.kpiName, X$2, _xlpm.factorName, $D5, _xlpm.headerText, "Dependent Variable: "&_xlpm.kpiName, _xlpm.regA, '2A Regression'!$A$1:$A$10000, _xlpm.regB, '2A Regression'!$B$1:$B$10000, _xlpm.regE, '2A Regression'!$E$1:$E$10000, _xlpm.headerRow, MATCH(_xlpm.headerText, _xlpm.regA, 0), _xlpm.nextHeaderRow, _xlfn.AGGREGATE(15, 6, ROW(_xlpm.regA)/((LEFT(_xlpm.regA,19)="Dependent Variable:")*(ROW(_xlpm.regA)>_xlpm.headerRow)), 1), _xlpm.searchStart, _xlpm.headerRow, _xlpm.searchEnd, IF(ISERROR(_xlpm.nextHeaderRow), 300, _xlpm.nextHeaderRow-1), _xlpm.factorPos, _xlfn.AGGREGATE(15, 6, ROW(_xlpm.regB)/((_xlpm.regB=_xlpm.factorName)*(ROW(_xlpm.regB)>=_xlpm.searchStart)*(ROW(_xlpm.regB)<=_xlpm.searchEnd)), 1), IF(ISERROR(_xlpm.factorPos), 0, INDEX(_xlpm.regE, _xlpm.factorPos)) )} -> 0
