Workbook

Sheet Instruction
B2: 这个文件主要用来整理MIA回归模型的结果，更新成给CS的模板
B3: • 自动更新"2A 回归Syntax"，Column A为X变量，Column B为Y变量（填充回归变量，多组回归同时进行时，按每组间间隔三行的形式向下填充）
B4: • 自动更新 2A Regression、2B RotationRule、2B FL、2C 均值、seenvsnoseen、Sample_Check
B5: • 需要维护2A 回归syntax C列及以后的公式
B6: • 更新“2D Mapping“，column A填写"2A Regression结果"对应的regression第几个regression结果表格（column L），column B填写table 对应的KPI，column C填写这个KPI是基于Total样本or部分样本
B7: • 2E.Analysis_MIA中，需要手动填写B列黄色部分(指回归x变量中除了factor以外的部分）
B9: 使用前需要先手动写的部分： | O9: G列是用于和运行时的变量名对照的，如果能完全保证顺序一致，不写也可以
B10: 2D Mapping中两列变量名称列（写希望交付结果时显示的变量名）
B11: 2E.Analysis_MIA/2E.ROE Scan中最左侧黄色方块（Brand dispo）
B12: 写入之后，2E中对应的图表才能分别出现变量名和数值
A15: 不适用的情况：
A16: 跑一次整个流程时，如果同时存在reg1，reg2…..那么他们的ind必须同时含同一个Brand dispo或者同时不含Brand dispo
A18: 因为2E中，有如图的约束（取0/1），如果我们运行时2A中得到的reg结果是同时存在：含不同的Brand dispo或者不含，会和该约束产生冲突，数据出错
A20: 在2E从2A中读取回归结果时，实际上只会从A列读取第一次出现的kpi
F22: 可以看到变量名相同时，数据都一样，也就是说如果reg2和reg1用同样的y变量就可能不被识别
A27: 建议：
A28: 1.ind相同时，可以只跑一组reg，罗列dep就可以
A29: 在运行时要注意config参数和Brand dispo的配套

Sheet 2A 回归syntax
A1: X变量 | B1: Y变量 | C1: SYNTAX1
A2: bumo | B2: dOEK1K2001 | C2: ="REGRESSION /MISSING PAIRWISE /STATISTICS COEFF OUTS R ANOVA /CRITERIA=PIN(.05) POUT(.10) /NOORIGIN /DEPENDENT "&B2&" /METHOD=ENTER "&_xlfn.TEXTJOIN(" ",,$A$2:$A$40) &". "
A3: Factor1 | B3: dK801 | C3: ="REGRESSION /MISSING PAIRWISE /STATISTICS COEFF OUTS R ANOVA /CRITERIA=PIN(.05) POUT(.10) /NOORIGIN /DEPENDENT "&B3&" /METHOD=ENTER "&_xlfn.TEXTJOIN(" ",,$A$2:$A$12) &". "
A4: Factor2 | B4: dIM1_Flip_V1_Slice06 | C4: ="REGRESSION /MISSING PAIRWISE /STATISTICS COEFF OUTS R ANOVA /CRITERIA=PIN(.05) POUT(.10) /NOORIGIN /DEPENDENT "&B4&" /METHOD=ENTER "&_xlfn.TEXTJOIN(" ",,$A$2:$A$12) &". "
A5: Factor3 | B5: dIM1_Flip_V1_Slice04 | C5: ="REGRESSION /MISSING PAIRWISE /STATISTICS COEFF OUTS R ANOVA /CRITERIA=PIN(.05) POUT(.10) /NOORIGIN /DEPENDENT "&B5&" /METHOD=ENTER "&_xlfn.TEXTJOIN(" ",,$A$2:$A$12) &". "
A6: Factor4 | C6: ="REGRESSION /MISSING PAIRWISE /STATISTICS COEFF OUTS R ANOVA /CRITERIA=PIN(.05) POUT(.10) /NOORIGIN /DEPENDENT "&B6&" /METHOD=ENTER "&_xlfn.TEXTJOIN(" ",,$A$2:$A$12) &". "
C7: ="REGRESSION /MISSING PAIRWISE /STATISTICS COEFF OUTS R ANOVA /CRITERIA=PIN(.05) POUT(.10) /NOORIGIN /DEPENDENT "&B7&" /METHOD=ENTER "&_xlfn.TEXTJOIN(" ",,$A$2:$A$12) &". "
C8: ="REGRESSION /MISSING PAIRWISE /STATISTICS COEFF OUTS R ANOVA /CRITERIA=PIN(.05) POUT(.10) /NOORIGIN /DEPENDENT "&B8&" /METHOD=ENTER "&_xlfn.TEXTJOIN(" ",,$A$2:$A$12) &". "
C9: ="REGRESSION /MISSING PAIRWISE /STATISTICS COEFF OUTS R ANOVA /CRITERIA=PIN(.05) POUT(.10) /NOORIGIN /DEPENDENT "&B9&" /METHOD=ENTER "&_xlfn.TEXTJOIN(" ",,$A$2:$A$12) &". "
C10: ="REGRESSION /MISSING PAIRWISE /STATISTICS COEFF OUTS R ANOVA /CRITERIA=PIN(.05) POUT(.10) /NOORIGIN /DEPENDENT "&B10&" /METHOD=ENTER "&_xlfn.TEXTJOIN(" ",,$A$2:$A$12) &". "
C11: ="REGRESSION /MISSING PAIRWISE /STATISTICS COEFF OUTS R ANOVA /CRITERIA=PIN(.05) POUT(.10) /NOORIGIN /DEPENDENT "&B11&" /METHOD=ENTER "&_xlfn.TEXTJOIN(" ",,$A$2:$A$12) &". "

Sheet 2A Regression
A1: Dependent Variable: dOEK1K2001
A2: Model Summary
A3: Model | B3: R | C3: R Square | D3: Adjusted R Square | E3: Std. Error of the Estimate
A4: 1 | B4: 0.36300039 | C4: 0.13176928 | D4: 0.12776453 | E4: 0.38485339
A5: a. Predictors: (Constant), bumo, Factor1, Factor2, Factor3, Factor4
A7: Coefficientsa
A8: Model | C8: Unstandardized Coefficients | E8: Standardized Coefficients | F8: t | G8: Sig. | H8: 95.0% Confidence Interval for B
C9: B | D9: Std. Error | E9: Beta | H9: Lower Bound | I9: Upper Bound
A10: 1 | B10: constant | C10: 0.16665874 | D10: 0.013736612 | F10: 12.132449 | G10: 0 | H10: 0.13970538 | I10: 0.1936121
B11: bumo | C11: 0.77806447 | D11: 0.063701256 | E11: 0.34799651 | F11: 12.214272 | G11: 0 | H11: 0.65307274 | I11: 0.90305619
B12: Factor1 | C12: 0.03555119 | D12: 0.011662459 | E12: 0.086184289 | F12: 3.0483443 | G12: 0.0023568367 | H12: 0.01266764 | I12: 0.058434739
B13: Factor2 | C13: 0.025866466 | D13: 0.011657058 | E13: 0.062685205 | F13: 2.2189532 | G13: 0.026696385 | H13: 0.0029935133 | I13: 0.048739419
B14: Factor3 | C14: 0.011306902 | D14: 0.011666225 | E14: 0.027403299 | F14: 0.96919974 | G14: 0.33266173 | H14: -0.011584037 | I14: 0.034197841
B15: Factor4 | C15: 0.011908132 | D15: 0.011658173 | E15: 0.028869659 | F15: 1.0214407 | G15: 0.30727359 | H15: -0.010967008 | I15: 0.034783272
B16: a. Dependent Variable: dOEK1K2001
A18: Dependent Variable: dK801
A19: Model Summary
A20: Model | B20: R | C20: R Square | D20: Adjusted R Square | E20: Std. Error of the Estimate
A21: 2 | B21: 0.34061459 | C21: 0.1160183 | D21: 0.11194089 | E21: 0.31158253
A22: a. Predictors: (Constant), bumo, Factor1, Factor2, Factor3, Factor4
A24: Coefficientsa
A25: Model | C25: Unstandardized Coefficients | E25: Standardized Coefficients | F25: t | G25: Sig. | H25: 95.0% Confidence Interval for B
C26: B | D26: Std. Error | E26: Beta | H26: Lower Bound | I26: Upper Bound
A27: 2 | B27: constant | C27: 0.096722743 | D27: 0.011121348 | F27: 8.6970343 | G27: 0 | H27: 0.074900937 | I27: 0.11854455
B28: bumo | C28: 0.5791145 | D28: 0.051573402 | E28: 0.3233936 | F28: 11.228937 | G28: 0 | H28: 0.4779195 | I28: 0.6803095
B29: Factor1 | C29: 0.040603923 | D29: 0.0094420849 | E29: 0.12289936 | F29: 4.3003133 | G29: 1.8592637e-05 | H29: 0.022077091 | I29: 0.059130755
B30: Factor2 | C30: 0.0037072089 | D30: 0.0094377125 | E30: 0.011217154 | F30: 0.39280799 | G30: 0.69453853 | H30: -0.014811044 | I30: 0.022225462
B31: Factor3 | C31: -0.0014792785 | D31: 0.009445134 | E31: -0.0044762758 | F31: -0.15661805 | G31: 0.87557504 | H31: -0.020012094 | I31: 0.017053537
B32: Factor4 | C32: -0.0071955615 | D32: 0.009438615 | E32: -0.021780627 | F32: -0.76235354 | G32: 0.44601487 | H32: -0.025715585 | I32: 0.011324462
B33: a. Dependent Variable: dK801
A35: Dependent Variable: dIM1_Flip_V1_Slice06
A36: Model Summary
A37: Model | B37: R | C37: R Square | D37: Adjusted R Square | E37: Std. Error of the Estimate
A38: 3 | B38: 0.3268481 | C38: 0.10682968 | D38: 0.10270989 | E38: 0.32824503
A39: a. Predictors: (Constant), bumo, Factor1, Factor2, Factor3, Factor4
A41: Coefficientsa
A42: Model | C42: Unstandardized Coefficients | E42: Standardized Coefficients | F42: t | G42: Sig. | H42: 95.0% Confidence Interval for B
C43: B | D43: Std. Error | E43: Beta | H43: Lower Bound | I43: Upper Bound
A44: 3 | B44: constant | C44: 0.09968249 | D44: 0.011716084 | F44: 8.5081747 | G44: 0 | H44: 0.076693719 | I44: 0.12267126
B45: bumo | C45: 0.56189232 | D45: 0.054331393 | E45: 0.2994236 | F45: 10.341946 | G45: 0 | H45: 0.45528571 | I45: 0.66849892
...

Sheet 2B RotationRule
B2: VariableID | C2: Name | D2: Lable | E2: Factor1 | F2: Factor2 | G2: Factor3 | H2: Factor4
B3: 1 | C3: instagram | D3: instagram | E3: 1
B4: 2 | C4: tiktok | D4: tiktok | F4: 1
B5: 3 | C5: youtube | D5: youtube | G5: 1
B6: 4 | C6: metro | D6: metro | H6: 1

Sheet 2B FL
A1: Spend time = 00:00:02
A2: Factor Result
A3: TIME= 2026/08/20 11:07:51
A4: Rotation Method= Procrustes Method
A7: Total Variance Explained
A8: Initial Eigenvalues
A9: Extraction Method: Principal Component Analysis.
A11: Component | B11: Total | C11: % of Variance | D11: Cumulative %
A12: Factor1 | B12: 1.9147562 | C12: 0.47868904 | D12: 0.47868904
A13: Factor2 | B13: 0.87841936 | C13: 0.21960484 | D13: 0.69829389
A14: Factor3 | B14: 0.65355877 | C14: 0.16338969 | D14: 0.86168358
A15: Factor4 | B15: 0.55326569 | C15: 0.13831642 | D15: 1
A17: Component Matrix
A18: Extraction Method: Principal Component Analysis.
A20: VariableID | B20: Variable | C20: Lable | D20: Factor1 | E20: Factor2 | F20: Factor3 | G20: Factor4
A21: 1 | B21: instagram | C21: instagram | D21: -0.69192803 | E21: -0.35128286 | F21: -0.62856967 | G21: 0.052307944
A22: 2 | B22: tiktok | C22: tiktok | D22: -0.71193673 | E22: -0.38053719 | F22: 0.46184885 | G22: 0.36746861
A23: 3 | B23: youtube | C23: youtube | D23: -0.78400898 | E23: 0.1015887 | F23: 0.19528107 | G23: -0.58040931
A24: 4 | B24: metro | C24: metro | D24: -0.56077429 | E24: 0.77452624 | F24: -0.083784686 | G24: 0.28039513
A26: Rotated Component Matrix
A27: Rotation Method: Procrustes with Kaiser Normalization.
A29: VariableID | B29: Variable | C29: Lable | D29: Factor1 | E29: Factor2 | F29: Factor3 | G29: Factor4
A30: 1 | B30: instagram | C30: instagram | D30: 0.97005745 | E30: 0.16536919 | F30: 0.16130812 | G30: 0.07497506
A31: 2 | B31: tiktok | C31: tiktok | D31: 0.16536919 | E31: 0.96618683 | F31: 0.18694774 | G31: 0.064703834
A32: 3 | B32: youtube | C32: youtube | D32: 0.16130812 | E32: 0.18694774 | F32: 0.9552891 | G32: 0.16264367
A33: 4 | B33: metro | C33: metro | D33: 0.07497506 | E33: 0.064703834 | F33: 0.16264367 | G33: 0.98170219
A35: Available Rotation Rule Matrix
A36: You can Copy this Matrix to Rotation Rule Sheet.
A38: VariableID | B38: Variable | C38: Lable | D38: Factor1 | E38: Factor2 | F38: Factor3 | G38: Factor4
A39: 1 | B39: instagram | C39: instagram | D39: 1
A40: 2 | B40: tiktok | C40: tiktok | E40: 1
A41: 3 | B41: youtube | C41: youtube | F41: 1
A42: 4 | B42: metro | C42: metro | G42: 1
A44: Component Score Coefficient Matrix
A46: VariableID | B46: Variable | C46: Lable | D46: Factor1 | E46: Factor2 | F46: Factor3 | G46: Factor4
A47: 1 | B47: instagram | C47: instagram | D47: 1.0850223 | E47: -0.15444923 | F47: -0.14469546 | G47: -0.048713712
A48: 2 | B48: tiktok | C48: tiktok | D48: -0.15444923 | E48: 1.0990275 | F48: -0.18385865 | G48: -0.030180239
A49: 3 | B49: youtube | C49: youtube | D49: -0.14469546 | E49: -0.18385865 | F49: 1.1352961 | G49: -0.1649215
A50: 4 | B50: metro | C50: metro | D50: -0.048713712 | E50: -0.030180239 | F50: -0.1649215 | G50: 1.0516718
A52: Unstandardized Component Score Coefficient Matrix
...

Sheet 2C 均值
A1: Original KPIs
A2: Variable | B2: N | C2: Min | D2: Max | E2: Mean | F2: Std
A3: K301 | B3: 1090.0031 | C3: 0 | D3: 1 | E3: 0.52060077 | F3: 0.49957543
A4: OEK1K2001 | B4: 1090.0031 | C4: 0 | D4: 1 | E4: 0.21654228 | F4: 0.411888
A5: K801 | B5: 1090.0031 | C5: 0 | D5: 1 | E5: 0.12479458 | F5: 0.33048584
A6: IM1_Flip_V1_Slice06 | B6: 567.45647 | C6: 0 | D6: 1 | E6: 0.26776808 | F6: 0.44279604
A7: IM1_Flip_V1_Slice04 | B7: 567.45647 | C7: 0 | D7: 1 | E7: 0.26438139 | F7: 0.44100325
A8: bumo | B8: 1090.0031 | C8: 0 | D8: 1 | E8: 0.034791491 | F8: 0.18325131
A9: Valid N (listwise) | B9: 567.45647
A11: Recoded KPIs
A12: Variable | B12: N | C12: Min | D12: Max | E12: Mean | F12: Std
A13: dK301 | B13: 1090.0031 | C13: 0 | D13: 1 | E13: 0.52060077 | F13: 0.49957543
A14: dOEK1K2001 | B14: 1090.0031 | C14: 0 | D14: 1 | E14: 0.21654228 | F14: 0.411888
A15: dK801 | B15: 1090.0031 | C15: 0 | D15: 1 | E15: 0.12479458 | F15: 0.33048584
A16: dIM1_Flip_V1_Slice06 | B16: 1090.0031 | C16: 0 | D16: 1 | E16: 0.13940027 | F16: 0.34636373
A17: dIM1_Flip_V1_Slice04 | B17: 1090.0031 | C17: 0 | D17: 1 | E17: 0.13763715 | F17: 0.34451875
A18: dbumo | B18: 1090.0031 | C18: 0 | D18: 1 | E18: 0.034791491 | F18: 0.18325131
A19: Valid N (listwise) | B19: 1090.0031
A21: Original Channels
A22: Variable | B22: N | C22: Min | D22: Max | E22: Mean | F22: Std
A23: instagram | B23: 1090.0031 | C23: 0 | D23: 1 | E23: 0.11498455 | F23: 0.3190033
A24: youtube | B24: 1090.0031 | C24: 0 | D24: 1 | E24: 0.18977624 | F24: 0.39212399
A25: tiktok | B25: 1090.0031 | C25: 0 | D25: 1 | E25: 0.11176344 | F25: 0.31507519
A26: metro | B26: 1090.0031 | C26: 0 | D26: 1 | E26: 0.14881822 | F26: 0.3559092
A27: Valid N (listwise) | B27: 1090.0031
A29: Recoded Channels
A30: Variable | B30: N | C30: Min | D30: Max | E30: Mean | F30: Std
A31: dAdloopTVC_V2_A51 | B31: 1090.0031 | C31: 0 | D31: 1 | E31: 0.080989789 | F31: 0.27281943
A32: dAdloopTVC_V1_A51 | B32: 1090.0031 | C32: 0 | D32: 1 | E32: 0.069643211 | F32: 0.25454476
A33: dAdloopTVC_V2_A52 | B33: 1090.0031 | C33: 0 | D33: 1 | E33: 0.12724377 | F33: 0.33324585
A34: dAdloopTVC_V1_A52 | B34: 1090.0031 | C34: 0 | D34: 1 | E34: 0.13638995 | F34: 0.34320217
A35: dAdloopTVC_V2_A53 | B35: 1090.0031 | C35: 0 | D35: 1 | E35: 0.077324347 | F35: 0.2671054
A36: dAdloopTVC_V1_A53 | B36: 1090.0031 | C36: 0 | D36: 1 | E36: 0.069789574 | F36: 0.25479205
A37: dAdloopKV_V4_A55 | B37: 1090.0031 | C37: 0 | D37: 1 | E37: 0.14881822 | F37: 0.3559092
A38: Valid N (listwise) | B38: 1090.0031

Sheet 2D Mapping
A1: 2A Regression结果Table中对应的不同KPI | D1: 手写 | G1: ind Variable | H1: 变量名称
A2: 第几个table | B2: Dependent Variable | C2: 模型Base | D2: 变量名称 | G2: instagram | H2: instagram
A3: 1 | B3: {=IF($A3="","",_xlfn.LET( _xlpm.n,$A3, _xlpm.allRows,'2A Regression'!$A:$A, _xlpm.matches,IF(LEFT(_xlpm.allRows,19)="Dependent Variable:",ROW(_xlpm.allRows),""), _xlpm.nthRow,SMALL(IF(_xlpm.matches<>"",_xlpm.matches),_xlpm.n), _xlpm.result,INDEX(_xlpm.allRows,_xlpm.nthRow), IFERROR(SUBSTITUTE(_xlpm.result,"Dependent Variable: ",""),"") ))} | C3: Total | D3: Brand Awareness | G3: youtube | H3: youtube
A4: 2 | B4: {=IF($A4="","",_xlfn.LET( _xlpm.n,$A4, _xlpm.allRows,'2A Regression'!$A:$A, _xlpm.matches,IF(LEFT(_xlpm.allRows,19)="Dependent Variable:",ROW(_xlpm.allRows),""), _xlpm.nthRow,SMALL(IF(_xlpm.matches<>"",_xlpm.matches),_xlpm.n), _xlpm.result,INDEX(_xlpm.allRows,_xlpm.nthRow), IFERROR(SUBSTITUTE(_xlpm.result,"Dependent Variable: ",""),"") ))} | C4: Total | D4: Brand Familiarity | G4: tiktok | H4: tiktok
A5: 3 | B5: {=IF($A5="","",_xlfn.LET( _xlpm.n,$A5, _xlpm.allRows,'2A Regression'!$A:$A, _xlpm.matches,IF(LEFT(_xlpm.allRows,19)="Dependent Variable:",ROW(_xlpm.allRows),""), _xlpm.nthRow,SMALL(IF(_xlpm.matches<>"",_xlpm.matches),_xlpm.n), _xlpm.result,INDEX(_xlpm.allRows,_xlpm.nthRow), IFERROR(SUBSTITUTE(_xlpm.result,"Dependent Variable: ",""),"") ))} | C5: Total | D5: Brand Consideration | G5: metro | H5: metro
A6: 4 | B6: {=IF($A6="","",_xlfn.LET( _xlpm.n,$A6, _xlpm.allRows,'2A Regression'!$A:$A, _xlpm.matches,IF(LEFT(_xlpm.allRows,19)="Dependent Variable:",ROW(_xlpm.allRows),""), _xlpm.nthRow,SMALL(IF(_xlpm.matches<>"",_xlpm.matches),_xlpm.n), _xlpm.result,INDEX(_xlpm.allRows,_xlpm.nthRow), IFERROR(SUBSTITUTE(_xlpm.result,"Dependent Variable: ",""),"") ))} | C6: Total | D6: Outstanding performance in taking portraits
A7: 5 | B7: {=IF($A7="","",_xlfn.LET( _xlpm.n,$A7, _xlpm.allRows,'2A Regression'!$A:$A, _xlpm.matches,IF(LEFT(_xlpm.allRows,19)="Dependent Variable:",ROW(_xlpm.allRows),""), _xlpm.nthRow,SMALL(IF(_xlpm.matches<>"",_xlpm.matches),_xlpm.n), _xlpm.result,INDEX(_xlpm.allRows,_xlpm.nthRow), IFERROR(SUBSTITUTE(_xlpm.result,"Dependent Variable: ",""),"") ))} | C7: Total
A8: 6 | B8: {=IF($A8="","",_xlfn.LET( _xlpm.n,$A8, _xlpm.allRows,'2A Regression'!$A:$A, _xlpm.matches,IF(LEFT(_xlpm.allRows,19)="Dependent Variable:",ROW(_xlpm.allRows),""), _xlpm.nthRow,SMALL(IF(_xlpm.matches<>"",_xlpm.matches),_xlpm.n), _xlpm.result,INDEX(_xlpm.allRows,_xlpm.nthRow), IFERROR(SUBSTITUTE(_xlpm.result,"Dependent Variable: ",""),"") ))} | C8: Total
A9: 7 | B9: {=IF($A9="","",_xlfn.LET( _xlpm.n,$A9, _xlpm.allRows,'2A Regression'!$A:$A, _xlpm.matches,IF(LEFT(_xlpm.allRows,19)="Dependent Variable:",ROW(_xlpm.allRows),""), _xlpm.nthRow,SMALL(IF(_xlpm.matches<>"",_xlpm.matches),_xlpm.n), _xlpm.result,INDEX(_xlpm.allRows,_xlpm.nthRow), IFERROR(SUBSTITUTE(_xlpm.result,"Dependent Variable: ",""),"") ))} | C9: Total
A10: 8 | B10: {=IF($A10="","",_xlfn.LET( _xlpm.n,$A10, _xlpm.allRows,'2A Regression'!$A:$A, _xlpm.matches,IF(LEFT(_xlpm.allRows,19)="Dependent Variable:",ROW(_xlpm.allRows),""), _xlpm.nthRow,SMALL(IF(_xlpm.matches<>"",_xlpm.matches),_xlpm.n), _xlpm.result,INDEX(_xlpm.allRows,_xlpm.nthRow), IFERROR(SUBSTITUTE(_xlpm.result,"Dependent Variable: ",""),"") ))} | C10: Total
A11: 9 | B11: {=IF($A11="","",_xlfn.LET( _xlpm.n,$A11, _xlpm.allRows,'2A Regression'!$A:$A, _xlpm.matches,IF(LEFT(_xlpm.allRows,19)="Dependent Variable:",ROW(_xlpm.allRows),""), _xlpm.nthRow,SMALL(IF(_xlpm.matches<>"",_xlpm.matches),_xlpm.n), _xlpm.result,INDEX(_xlpm.allRows,_xlpm.nthRow), IFERROR(SUBSTITUTE(_xlpm.result,"Dependent Variable: ",""),"") ))}
A12: 10 | B12: {=IF($A12="","",_xlfn.LET( _xlpm.n,$A12, _xlpm.allRows,'2A Regression'!$A:$A, _xlpm.matches,IF(LEFT(_xlpm.allRows,19)="Dependent Variable:",ROW(_xlpm.allRows),""), _xlpm.nthRow,SMALL(IF(_xlpm.matches<>"",_xlpm.matches),_xlpm.n), _xlpm.result,INDEX(_xlpm.allRows,_xlpm.nthRow), IFERROR(SUBSTITUTE(_xlpm.result,"Dependent Variable: ",""),"") ))}
A13: 11 | B13: {=IF($A13="","",_xlfn.LET( _xlpm.n,$A13, _xlpm.allRows,'2A Regression'!$A:$A, _xlpm.matches,IF(LEFT(_xlpm.allRows,19)="Dependent Variable:",ROW(_xlpm.allRows),""), _xlpm.nthRow,SMALL(IF(_xlpm.matches<>"",_xlpm.matches),_xlpm.n), _xlpm.result,INDEX(_xlpm.allRows,_xlpm.nthRow), IFERROR(SUBSTITUTE(_xlpm.result,"Dependent Variable: ",""),"") ))}
A14: 12 | B14: {=IF($A14="","",_xlfn.LET( _xlpm.n,$A14, _xlpm.allRows,'2A Regression'!$A:$A, _xlpm.matches,IF(LEFT(_xlpm.allRows,19)="Dependent Variable:",ROW(_xlpm.allRows),""), _xlpm.nthRow,SMALL(IF(_xlpm.matches<>"",_xlpm.matches),_xlpm.n), _xlpm.result,INDEX(_xlpm.allRows,_xlpm.nthRow), IFERROR(SUBSTITUTE(_xlpm.result,"Dependent Variable: ",""),"") ))}
A15: 13 | B15: {=IF($A15="","",_xlfn.LET( _xlpm.n,$A15, _xlpm.allRows,'2A Regression'!$A:$A, _xlpm.matches,IF(LEFT(_xlpm.allRows,19)="Dependent Variable:",ROW(_xlpm.allRows),""), _xlpm.nthRow,SMALL(IF(_xlpm.matches<>"",_xlpm.matches),_xlpm.n), _xlpm.result,INDEX(_xlpm.allRows,_xlpm.nthRow), IFERROR(SUBSTITUTE(_xlpm.result,"Dependent Variable: ",""),"") ))}
A16: 14 | B16: {=IF($A16="","",_xlfn.LET( _xlpm.n,$A16, _xlpm.allRows,'2A Regression'!$A:$A, _xlpm.matches,IF(LEFT(_xlpm.allRows,19)="Dependent Variable:",ROW(_xlpm.allRows),""), _xlpm.nthRow,SMALL(IF(_xlpm.matches<>"",_xlpm.matches),_xlpm.n), _xlpm.result,INDEX(_xlpm.allRows,_xlpm.nthRow), IFERROR(SUBSTITUTE(_xlpm.result,"Dependent Variable: ",""),"") ))}
A17: 15 | B17: {=IF($A17="","",_xlfn.LET( _xlpm.n,$A17, _xlpm.allRows,'2A Regression'!$A:$A, _xlpm.matches,IF(LEFT(_xlpm.allRows,19)="Dependent Variable:",ROW(_xlpm.allRows),""), _xlpm.nthRow,SMALL(IF(_xlpm.matches<>"",_xlpm.matches),_xlpm.n), _xlpm.result,INDEX(_xlpm.allRows,_xlpm.nthRow), IFERROR(SUBSTITUTE(_xlpm.result,"Dependent Variable: ",""),"") ))}
A18: 16 | B18: {=IF($A18="","",_xlfn.LET( _xlpm.n,$A18, _xlpm.allRows,'2A Regression'!$A:$A, _xlpm.matches,IF(LEFT(_xlpm.allRows,19)="Dependent Variable:",ROW(_xlpm.allRows),""), _xlpm.nthRow,SMALL(IF(_xlpm.matches<>"",_xlpm.matches),_xlpm.n), _xlpm.result,INDEX(_xlpm.allRows,_xlpm.nthRow), IFERROR(SUBSTITUTE(_xlpm.result,"Dependent Variable: ",""),"") ))}
A19: 17 | B19: {=IF($A19="","",_xlfn.LET( _xlpm.n,$A19, _xlpm.allRows,'2A Regression'!$A:$A, _xlpm.matches,IF(LEFT(_xlpm.allRows,19)="Dependent Variable:",ROW(_xlpm.allRows),""), _xlpm.nthRow,SMALL(IF(_xlpm.matches<>"",_xlpm.matches),_xlpm.n), _xlpm.result,INDEX(_xlpm.allRows,_xlpm.nthRow), IFERROR(SUBSTITUTE(_xlpm.result,"Dependent Variable: ",""),"") ))}
A20: 18 | B20: {=IF($A20="","",_xlfn.LET( _xlpm.n,$A20, _xlpm.allRows,'2A Regression'!$A:$A, _xlpm.matches,IF(LEFT(_xlpm.allRows,19)="Dependent Variable:",ROW(_xlpm.allRows),""), _xlpm.nthRow,SMALL(IF(_xlpm.matches<>"",_xlpm.matches),_xlpm.n), _xlpm.result,INDEX(_xlpm.allRows,_xlpm.nthRow), IFERROR(SUBSTITUTE(_xlpm.result,"Dependent Variable: ",""),"") ))}
A21: 19 | B21: {=IF($A21="","",_xlfn.LET( _xlpm.n,$A21, _xlpm.allRows,'2A Regression'!$A:$A, _xlpm.matches,IF(LEFT(_xlpm.allRows,19)="Dependent Variable:",ROW(_xlpm.allRows),""), _xlpm.nthRow,SMALL(IF(_xlpm.matches<>"",_xlpm.matches),_xlpm.n), _xlpm.result,INDEX(_xlpm.allRows,_xlpm.nthRow), IFERROR(SUBSTITUTE(_xlpm.result,"Dependent Variable: ",""),"") ))}
A22: 20 | B22: {=IF($A22="","",_xlfn.LET( _xlpm.n,$A22, _xlpm.allRows,'2A Regression'!$A:$A, _xlpm.matches,IF(LEFT(_xlpm.allRows,19)="Dependent Variable:",ROW(_xlpm.allRows),""), _xlpm.nthRow,SMALL(IF(_xlpm.matches<>"",_xlpm.matches),_xlpm.n), _xlpm.result,INDEX(_xlpm.allRows,_xlpm.nthRow), IFERROR(SUBSTITUTE(_xlpm.result,"Dependent Variable: ",""),"") ))}
A23: 21
A24: 22
A25: 23
A26: 24
A27: 25
A28: 26
A29: 27
A30: 28
A31: 29
A32: 30
A33: 31
A34: 32
... A52: 50

Sheet 2E.Analysis_MIA
D1: 模型Base的样本 | E1: {=TRANSPOSE('2D Mapping'!C3:C22)} | F1: Total | G1: Total | H1: Total | I1: Total | J1: Total | K1: Total | L1: Total | M1: 0 | N1: 0 | O1: 0 | P1: 0 | Q1: 0 | R1: 0 | S1: 0 | T1: 0 | U1: 0 | V1: 0 | W1: 0 | X1: 0 | Y1: {=TRANSPOSE('2D Mapping'!D3:D22)} | Z1: {=TRANSPOSE('2D Mapping'!E3:E22)} | AA1: {=TRANSPOSE('2D Mapping'!F3:F22)} | AB1: {=TRANSPOSE('2D Mapping'!G3:G22)} | AC1: {=TRANSPOSE('2D Mapping'!H3:H22)} | AD1: {=TRANSPOSE('2D Mapping'!I3:I22)} | AE1: {=TRANSPOSE('2D Mapping'!J3:J22)} | AF1: {=TRANSPOSE('2D Mapping'!K3:K22)} | ... BB1: {=TRANSPOSE('2D Mapping'!AG3:AG22)}
A2: >>请输入： | D2: 标准化系数（回归模型结果） | E2: {=TRANSPOSE('2D Mapping'!B3:B52)} | Y2: 0 | Z2: 0 | AA2: 0 | AB2: 0 | AC2: 0 | AD2: 0 | AE2: 0 | AF2: 0 | AG2: 0 | AH2: 0 | AI2: 0 | AJ2: 0 | AK2: 0 | AL2: 0 | AM2: 0 | AN2: 0 | AO2: 0 | AP2: 0 | AQ2: 0 | AR2: 0 | AS2: 0 | AT2: 0 | AU2: 0 | AV2: 0 | AW2: 0 | AX2: 0 | AY2: 0 | AZ2: 0 | BA2: 0 | BB2: 0
D3: Factor1 | E3: {=_xlfn.LET( _xlpm.kpiName, E$2, _xlpm.factorName, $D3, _xlpm.headerText, "Dependent Variable: "&_xlpm.kpiName, _xlpm.regA, '2A Regression'!$A$1:$A$10000, _xlpm.regB, '2A Regression'!$B$1:$B$10000, _xlpm.regE, '2A Regression'!$E$1:$E$10000, _xlpm.headerRow, MATCH(_xlpm.headerText, _xlpm.regA, 0), _xlpm.nextHeaderRow, _xlfn.AGGREGATE(15, 6, ROW(_xlpm.regA)/((LEFT(_xlpm.regA,19)="Dependent Variable:")*(ROW(_xlpm.regA)>_xlpm.headerRow)), 1), _xlpm.searchStart, _xlpm.headerRow, _xlpm.searchEnd, IF(ISERROR(_xlpm.nextHeaderRow), 300, _xlpm.nextHeaderRow-1), _xlpm.factorPos, _xlfn.AGGREGATE(15, 6, ROW(_xlpm.regB)/((_xlpm.regB=_xlpm.factorName)*(ROW(_xlpm.regB)>=_xlpm.searchStart)*(ROW(_xlpm.regB)<=_xlpm.searchEnd)), 1), IF(ISERROR(_xlpm.factorPos), 0, INDEX(_xlpm.regE, _xlpm.factorPos)) )} | F3: {=_xlfn.LET( _xlpm.kpiName, F$2, _xlpm.factorName, $D3, _xlpm.headerText, "Dependent Variable: "&_xlpm.kpiName, _xlpm.regA, '2A Regression'!$A$1:$A$10000, _xlpm.regB, '2A Regression'!$B$1:$B$10000, _xlpm.regE, '2A Regression'!$E$1:$E$10000, _xlpm.headerRow, MATCH(_xlpm.headerText, _xlpm.regA, 0), _xlpm.nextHeaderRow, _xlfn.AGGREGATE(15, 6, ROW(_xlpm.regA)/((LEFT(_xlpm.regA,19)="Dependent Variable:")*(ROW(_xlpm.regA)>_xlpm.headerRow)), 1), _xlpm.searchStart, _xlpm.headerRow, _xlpm.searchEnd, IF(ISERROR(_xlpm.nextHeaderRow), 300, _xlpm.nextHeaderRow-1), _xlpm.factorPos, _xlfn.AGGREGATE(15, 6, ROW(_xlpm.regB)/((_xlpm.regB=_xlpm.factorName)*(ROW(_xlpm.regB)>=_xlpm.searchStart)*(ROW(_xlpm.regB)<=_xlpm.searchEnd)), 1), IF(ISERROR(_xlpm.factorPos), 0, INDEX(_xlpm.regE, _xlpm.factorPos)) )} | G3: {=_xlfn.LET( _xlpm.kpiName, G$2, _xlpm.factorName, $D3, _xlpm.headerText, "Dependent Variable: "&_xlpm.kpiName, _xlpm.regA, '2A Regression'!$A$1:$A$10000, _xlpm.regB, '2A Regression'!$B$1:$B$10000, _xlpm.regE, '2A Regression'!$E$1:$E$10000, _xlpm.headerRow, MATCH(_xlpm.headerText, _xlpm.regA, 0), _xlpm.nextHeaderRow, _xlfn.AGGREGATE(15, 6, ROW(_xlpm.regA)/((LEFT(_xlpm.regA,19)="Dependent Variable:")*(ROW(_xlpm.regA)>_xlpm.headerRow)), 1), _xlpm.searchStart, _xlpm.headerRow, _xlpm.searchEnd, IF(ISERROR(_xlpm.nextHeaderRow), 300, _xlpm.nextHeaderRow-1), _xlpm.factorPos, _xlfn.AGGREGATE(15, 6, ROW(_xlpm.regB)/((_xlpm.regB=_xlpm.factorName)*(ROW(_xlpm.regB)>=_xlpm.searchStart)*(ROW(_xlpm.regB)<=_xlpm.searchEnd)), 1), IF(ISERROR(_xlpm.factorPos), 0, INDEX(_xlpm.regE, _xlpm.factorPos)) )} | H3: {=_xlfn.LET( _xlpm.kpiName, H$2, _xlpm.factorName, $D3, _xlpm.headerText, "Dependent Variable: "&_xlpm.kpiName, _xlpm.regA, '2A Regression'!$A$1:$A$10000, _xlpm.regB, '2A Regression'!$B$1:$B$10000, _xlpm.regE, '2A Regression'!$E$1:$E$10000, _xlpm.headerRow, MATCH(_xlpm.headerText, _xlpm.regA, 0), _xlpm.nextHeaderRow, _xlfn.AGGREGATE(15, 6, ROW(_xlpm.regA)/((LEFT(_xlpm.regA,19)="Dependent Variable:")*(ROW(_xlpm.regA)>_xlpm.headerRow)), 1), _xlpm.searchStart, _xlpm.headerRow, _xlpm.searchEnd, IF(ISERROR(_xlpm.nextHeaderRow), 300, _xlpm.nextHeaderRow-1), _xlpm.factorPos, _xlfn.AGGREGATE(15, 6, ROW(_xlpm.regB)/((_xlpm.regB=_xlpm.factorName)*(ROW(_xlpm.regB)>=_xlpm.searchStart)*(ROW(_xlpm.regB)<=_xlpm.searchEnd)), 1), IF(ISERROR(_xlpm.factorPos), 0, INDEX(_xlpm.regE, _xlpm.factorPos)) )} | I3: {=_xlfn.LET( _xlpm.kpiName, I$2, _xlpm.factorName, $D3, _xlpm.headerText, "Dependent Variable: "&_xlpm.kpiName, _xlpm.regA, '2A Regression'!$A$1:$A$10000, _xlpm.regB, '2A Regression'!$B$1:$B$10000, _xlpm.regE, '2A Regression'!$E$1:$E$10000, _xlpm.headerRow, MATCH(_xlpm.headerText, _xlpm.regA, 0), _xlpm.nextHeaderRow, _xlfn.AGGREGATE(15, 6, ROW(_xlpm.regA)/((LEFT(_xlpm.regA,19)="Dependent Variable:")*(ROW(_xlpm.regA)>_xlpm.headerRow)), 1), _xlpm.searchStart, _xlpm.headerRow, _xlpm.searchEnd, IF(ISERROR(_xlpm.nextHeaderRow), 300, _xlpm.nextHeaderRow-1), _xlpm.factorPos, _xlfn.AGGREGATE(15, 6, ROW(_xlpm.regB)/((_xlpm.regB=_xlpm.factorName)*(ROW(_xlpm.regB)>=_xlpm.searchStart)*(ROW(_xlpm.regB)<=_xlpm.searchEnd)), 1), IF(ISERROR(_xlpm.factorPos), 0, INDEX(_xlpm.regE, _xlpm.factorPos)) )} | J3: {=_xlfn.LET( _xlpm.kpiName, J$2, _xlpm.factorName, $D3, _xlpm.headerText, "Dependent Variable: "&_xlpm.kpiName, _xlpm.regA, '2A Regression'!$A$1:$A$10000, _xlpm.regB, '2A Regression'!$B$1:$B$10000, _xlpm.regE, '2A Regression'!$E$1:$E$10000, _xlpm.headerRow, MATCH(_xlpm.headerText, _xlpm.regA, 0), _xlpm.nextHeaderRow, _xlfn.AGGREGATE(15, 6, ROW(_xlpm.regA)/((LEFT(_xlpm.regA,19)="Dependent Variable:")*(ROW(_xlpm.regA)>_xlpm.headerRow)), 1), _xlpm.searchStart, _xlpm.headerRow, _xlpm.searchEnd, IF(ISERROR(_xlpm.nextHeaderRow), 300, _xlpm.nextHeaderRow-1), _xlpm.factorPos, _xlfn.AGGREGATE(15, 6, ROW(_xlpm.regB)/((_xlpm.regB=_xlpm.factorName)*(ROW(_xlpm.regB)>=_xlpm.searchStart)*(ROW(_xlpm.regB)<=_xlpm.searchEnd)), 1), IF(ISERROR(_xlpm.factorPos), 0, INDEX(_xlpm.regE, _xlpm.factorPos)) )} | K3: {=_xlfn.LET( _xlpm.kpiName, K$2, _xlpm.factorName, $D3, _xlpm.headerText, "Dependent Variable: "&_xlpm.kpiName, _xlpm.regA, '2A Regression'!$A$1:$A$10000, _xlpm.regB, '2A Regression'!$B$1:$B$10000, _xlpm.regE, '2A Regression'!$E$1:$E$10000, _xlpm.headerRow, MATCH(_xlpm.headerText, _xlpm.regA, 0), _xlpm.nextHeaderRow, _xlfn.AGGREGATE(15, 6, ROW(_xlpm.regA)/((LEFT(_xlpm.regA,19)="Dependent Variable:")*(ROW(_xlpm.regA)>_xlpm.headerRow)), 1), _xlpm.searchStart, _xlpm.headerRow, _xlpm.searchEnd, IF(ISERROR(_xlpm.nextHeaderRow), 300, _xlpm.nextHeaderRow-1), _xlpm.factorPos, _xlfn.AGGREGATE(15, 6, ROW(_xlpm.regB)/((_xlpm.regB=_xlpm.factorName)*(ROW(_xlpm.regB)>=_xlpm.searchStart)*(ROW(_xlpm.regB)<=_xlpm.searchEnd)), 1), IF(ISERROR(_xlpm.factorPos), 0, INDEX(_xlpm.regE, _xlpm.factorPos)) )} | L3: {=_xlfn.LET( _xlpm.kpiName, L$2, _xlpm.factorName, $D3, _xlpm.headerText, "Dependent Variable: "&_xlpm.kpiName, _xlpm.regA, '2A Regression'!$A$1:$A$10000, _xlpm.regB, '2A Regression'!$B$1:$B$10000, _xlpm.regE, '2A Regression'!$E$1:$E$10000, _xlpm.headerRow, MATCH(_xlpm.headerText, _xlpm.regA, 0), _xlpm.nextHeaderRow, _xlfn.AGGREGATE(15, 6, ROW(_xlpm.regA)/((LEFT(_xlpm.regA,19)="Dependent Variable:")*(ROW(_xlpm.regA)>_xlpm.headerRow)), 1), _xlpm.searchStart, _xlpm.headerRow, _xlpm.searchEnd, IF(ISERROR(_xlpm.nextHeaderRow), 300, _xlpm.nextHeaderRow-1), _xlpm.factorPos, _xlfn.AGGREGATE(15, 6, ROW(_xlpm.regB)/((_xlpm.regB=_xlpm.factorName)*(ROW(_xlpm.regB)>=_xlpm.searchStart)*(ROW(_xlpm.regB)<=_xlpm.searchEnd)), 1), IF(ISERROR(_xlpm.factorPos), 0, INDEX(_xlpm.regE, _xlpm.factorPos)) )} | ... BB3: {=_xlfn.LET( _xlpm.kpiName, BB$2, _xlpm.factorName, $D3, _xlpm.headerText, "Dependent Variable: "&_xlpm.kpiName, _xlpm.regA, '2A Regression'!$A$1:$A$10000, _xlpm.regB, '2A Regression'!$B$1:$B$10000, _xlpm.regE, '2A Regression'!$E$1:$E$10000, _xlpm.headerRow, MATCH(_xlpm.headerText, _xlpm.regA, 0), _xlpm.nextHeaderRow, _xlfn.AGGREGATE(15, 6, ROW(_xlpm.regA)/((LEFT(_xlpm.regA,19)="Dependent Variable:")*(ROW(_xlpm.regA)>_xlpm.headerRow)), 1), _xlpm.searchStart, _xlpm.headerRow, _xlpm.searchEnd, IF(ISERROR(_xlpm.nextHeaderRow), 300, _xlpm.nextHeaderRow-1), _xlpm.factorPos, _xlfn.AGGREGATE(15, 6, ROW(_xlpm.regB)/((_xlpm.regB=_xlpm.factorName)*(ROW(_xlpm.regB)>=_xlpm.searchStart)*(ROW(_xlpm.regB)<=_xlpm.searchEnd)), 1), IF(ISERROR(_xlpm.factorPos), 0, INDEX(_xlpm.regE, _xlpm.factorPos)) )}
A4: 是否有brand dispo信息（Yes：1，No：0） | B4: 1 | D4: Factor2 | E4: {=_xlfn.LET( _xlpm.kpiName, E$2, _xlpm.factorName, $D4, _xlpm.headerText, "Dependent Variable: "&_xlpm.kpiName, _xlpm.regA, '2A Regression'!$A$1:$A$10000, _xlpm.regB, '2A Regression'!$B$1:$B$10000, _xlpm.regE, '2A Regression'!$E$1:$E$10000, _xlpm.headerRow, MATCH(_xlpm.headerText, _xlpm.regA, 0), _xlpm.nextHeaderRow, _xlfn.AGGREGATE(15, 6, ROW(_xlpm.regA)/((LEFT(_xlpm.regA,19)="Dependent Variable:")*(ROW(_xlpm.regA)>_xlpm.headerRow)), 1), _xlpm.searchStart, _xlpm.headerRow, _xlpm.searchEnd, IF(ISERROR(_xlpm.nextHeaderRow), 300, _xlpm.nextHeaderRow-1), _xlpm.factorPos, _xlfn.AGGREGATE(15, 6, ROW(_xlpm.regB)/((_xlpm.regB=_xlpm.factorName)*(ROW(_xlpm.regB)>=_xlpm.searchStart)*(ROW(_xlpm.regB)<=_xlpm.searchEnd)), 1), IF(ISERROR(_xlpm.factorPos), 0, INDEX(_xlpm.regE, _xlpm.factorPos)) )} | F4: {=_xlfn.LET( _xlpm.kpiName, F$2, _xlpm.factorName, $D4, _xlpm.headerText, "Dependent Variable: "&_xlpm.kpiName, _xlpm.regA, '2A Regression'!$A$1:$A$10000, _xlpm.regB, '2A Regression'!$B$1:$B$10000, _xlpm.regE, '2A Regression'!$E$1:$E$10000, _xlpm.headerRow, MATCH(_xlpm.headerText, _xlpm.regA, 0), _xlpm.nextHeaderRow, _xlfn.AGGREGATE(15, 6, ROW(_xlpm.regA)/((LEFT(_xlpm.regA,19)="Dependent Variable:")*(ROW(_xlpm.regA)>_xlpm.headerRow)), 1), _xlpm.searchStart, _xlpm.headerRow, _xlpm.searchEnd, IF(ISERROR(_xlpm.nextHeaderRow), 300, _xlpm.nextHeaderRow-1), _xlpm.factorPos, _xlfn.AGGREGATE(15, 6, ROW(_xlpm.regB)/((_xlpm.regB=_xlpm.factorName)*(ROW(_xlpm.regB)>=_xlpm.searchStart)*(ROW(_xlpm.regB)<=_xlpm.searchEnd)), 1), IF(ISERROR(_xlpm.factorPos), 0, INDEX(_xlpm.regE, _xlpm.factorPos)) )} | G4: {=_xlfn.LET( _xlpm.kpiName, G$2, _xlpm.factorName, $D4, _xlpm.headerText, "Dependent Variable: "&_xlpm.kpiName, _xlpm.regA, '2A Regression'!$A$1:$A$10000, _xlpm.regB, '2A Regression'!$B$1:$B$10000, _xlpm.regE, '2A Regression'!$E$1:$E$10000, _xlpm.headerRow, MATCH(_xlpm.headerText, _xlpm.regA, 0), _xlpm.nextHeaderRow, _xlfn.AGGREGATE(15, 6, ROW(_xlpm.regA)/((LEFT(_xlpm.regA,19)="Dependent Variable:")*(ROW(_xlpm.regA)>_xlpm.headerRow)), 1), _xlpm.searchStart, _xlpm.headerRow, _xlpm.searchEnd, IF(ISERROR(_xlpm.nextHeaderRow), 300, _xlpm.nextHeaderRow-1), _xlpm.factorPos, _xlfn.AGGREGATE(15, 6, ROW(_xlpm.regB)/((_xlpm.regB=_xlpm.factorName)*(ROW(_xlpm.regB)>=_xlpm.searchStart)*(ROW(_xlpm.regB)<=_xlpm.searchEnd)), 1), IF(ISERROR(_xlpm.factorPos), 0, INDEX(_xlpm.regE, _xlpm.factorPos)) )} | H4: {=_xlfn.LET( _xlpm.kpiName, H$2, _xlpm.factorName, $D4, _xlpm.headerText, "Dependent Variable: "&_xlpm.kpiName, _xlpm.regA, '2A Regression'!$A$1:$A$10000, _xlpm.regB, '2A Regression'!$B$1:$B$10000, _xlpm.regE, '2A Regression'!$E$1:$E$10000, _xlpm.headerRow, MATCH(_xlpm.headerText, _xlpm.regA, 0), _xlpm.nextHeaderRow, _xlfn.AGGREGATE(15, 6, ROW(_xlpm.regA)/((LEFT(_xlpm.regA,19)="Dependent Variable:")*(ROW(_xlpm.regA)>_xlpm.headerRow)), 1), _xlpm.searchStart, _xlpm.headerRow, _xlpm.searchEnd, IF(ISERROR(_xlpm.nextHeaderRow), 300, _xlpm.nextHeaderRow-1), _xlpm.factorPos, _xlfn.AGGREGATE(15, 6, ROW(_xlpm.regB)/((_xlpm.regB=_xlpm.factorName)*(ROW(_xlpm.regB)>=_xlpm.searchStart)*(ROW(_xlpm.regB)<=_xlpm.searchEnd)), 1), IF(ISERROR(_xlpm.factorPos), 0, INDEX(_xlpm.regE, _xlpm.factorPos)) )} | I4: {=_xlfn.LET( _xlpm.kpiName, I$2, _xlpm.factorName, $D4, _xlpm.headerText, "Dependent Variable: "&_xlpm.kpiName, _xlpm.regA, '2A Regression'!$A$1:$A$10000, _xlpm.regB, '2A Regression'!$B$1:$B$10000, _xlpm.regE, '2A Regression'!$E$1:$E$10000, _xlpm.headerRow, MATCH(_xlpm.headerText, _xlpm.regA, 0), _xlpm.nextHeaderRow, _xlfn.AGGREGATE(15, 6, ROW(_xlpm.regA)/((LEFT(_xlpm.regA,19)="Dependent Variable:")*(ROW(_xlpm.regA)>_xlpm.headerRow)), 1), _xlpm.searchStart, _xlpm.headerRow, _xlpm.searchEnd, IF(ISERROR(_xlpm.nextHeaderRow), 300, _xlpm.nextHeaderRow-1), _xlpm.factorPos, _xlfn.AGGREGATE(15, 6, ROW(_xlpm.regB)/((_xlpm.regB=_xlpm.factorName)*(ROW(_xlpm.regB)>=_xlpm.searchStart)*(ROW(_xlpm.regB)<=_xlpm.searchEnd)), 1), IF(ISERROR(_xlpm.factorPos), 0, INDEX(_xlpm.regE, _xlpm.factorPos)) )} | J4: {=_xlfn.LET( _xlpm.kpiName, J$2, _xlpm.factorName, $D4, _xlpm.headerText, "Dependent Variable: "&_xlpm.kpiName, _xlpm.regA, '2A Regression'!$A$1:$A$10000, _xlpm.regB, '2A Regression'!$B$1:$B$10000, _xlpm.regE, '2A Regression'!$E$1:$E$10000, _xlpm.headerRow, MATCH(_xlpm.headerText, _xlpm.regA, 0), _xlpm.nextHeaderRow, _xlfn.AGGREGATE(15, 6, ROW(_xlpm.regA)/((LEFT(_xlpm.regA,19)="Dependent Variable:")*(ROW(_xlpm.regA)>_xlpm.headerRow)), 1), _xlpm.searchStart, _xlpm.headerRow, _xlpm.searchEnd, IF(ISERROR(_xlpm.nextHeaderRow), 300, _xlpm.nextHeaderRow-1), _xlpm.factorPos, _xlfn.AGGREGATE(15, 6, ROW(_xlpm.regB)/((_xlpm.regB=_xlpm.factorName)*(ROW(_xlpm.regB)>=_xlpm.searchStart)*(ROW(_xlpm.regB)<=_xlpm.searchEnd)), 1), IF(ISERROR(_xlpm.factorPos), 0, INDEX(_xlpm.regE, _xlpm.factorPos)) )} | K4: {=_xlfn.LET( _xlpm.kpiName, K$2, _xlpm.factorName, $D4, _xlpm.headerText, "Dependent Variable: "&_xlpm.kpiName, _xlpm.regA, '2A Regression'!$A$1:$A$10000, _xlpm.regB, '2A Regression'!$B$1:$B$10000, _xlpm.regE, '2A Regression'!$E$1:$E$10000, _xlpm.headerRow, MATCH(_xlpm.headerText, _xlpm.regA, 0), _xlpm.nextHeaderRow, _xlfn.AGGREGATE(15, 6, ROW(_xlpm.regA)/((LEFT(_xlpm.regA,19)="Dependent Variable:")*(ROW(_xlpm.regA)>_xlpm.headerRow)), 1), _xlpm.searchStart, _xlpm.headerRow, _xlpm.searchEnd, IF(ISERROR(_xlpm.nextHeaderRow), 300, _xlpm.nextHeaderRow-1), _xlpm.factorPos, _xlfn.AGGREGATE(15, 6, ROW(_xlpm.regB)/((_xlpm.regB=_xlpm.factorName)*(ROW(_xlpm.regB)>=_xlpm.searchStart)*(ROW(_xlpm.regB)<=_xlpm.searchEnd)), 1), IF(ISERROR(_xlpm.factorPos), 0, INDEX(_xlpm.regE, _xlpm.factorPos)) )} | L4: {=_xlfn.LET( _xlpm.kpiName, L$2, _xlpm.factorName, $D4, _xlpm.headerText, "Dependent Variable: "&_xlpm.kpiName, _xlpm.regA, '2A Regression'!$A$1:$A$10000, _xlpm.regB, '2A Regression'!$B$1:$B$10000, _xlpm.regE, '2A Regression'!$E$1:$E$10000, _xlpm.headerRow, MATCH(_xlpm.headerText, _xlpm.regA, 0), _xlpm.nextHeaderRow, _xlfn.AGGREGATE(15, 6, ROW(_xlpm.regA)/((LEFT(_xlpm.regA,19)="Dependent Variable:")*(ROW(_xlpm.regA)>_xlpm.headerRow)), 1), _xlpm.searchStart, _xlpm.headerRow, _xlpm.searchEnd, IF(ISERROR(_xlpm.nextHeaderRow), 300, _xlpm.nextHeaderRow-1), _xlpm.factorPos, _xlfn.AGGREGATE(15, 6, ROW(_xlpm.regB)/((_xlpm.regB=_xlpm.factorName)*(ROW(_xlpm.regB)>=_xlpm.searchStart)*(ROW(_xlpm.regB)<=_xlpm.searchEnd)), 1), IF(ISERROR(_xlpm.factorPos), 0, INDEX(_xlpm.regE, _xlpm.factorPos)) )} | ... BB4: {=_xlfn.LET( _xlpm.kpiName, BB$2, _xlpm.factorName, $D4, _xlpm.headerText, "Dependent Variable: "&_xlpm.kpiName, _xlpm.regA, '2A Regression'!$A$1:$A$10000, _xlpm.regB, '2A Regression'!$B$1:$B$10000, _xlpm.regE, '2A Regression'!$E$1:$E$10000, _xlpm.headerRow, MATCH(_xlpm.headerText, _xlpm.regA, 0), _xlpm.nextHeaderRow, _xlfn.AGGREGATE(15, 6, ROW(_xlpm.regA)/((LEFT(_xlpm.regA,19)="Dependent Variable:")*(ROW(_xlpm.regA)>_xlpm.headerRow)), 1), _xlpm.searchStart, _xlpm.headerRow, _xlpm.searchEnd, IF(ISERROR(_xlpm.nextHeaderRow), 300, _xlpm.nextHeaderRow-1), _xlpm.factorPos, _xlfn.AGGREGATE(15, 6, ROW(_xlpm.regB)/((_xlpm.regB=_xlpm.factorName)*(ROW(_xlpm.regB)>=_xlpm.searchStart)*(ROW(_xlpm.regB)<=_xlpm.searchEnd)), 1), IF(ISERROR(_xlpm.factorPos), 0, INDEX(_xlpm.regE, _xlpm.factorPos)) )}
D5: Factor3 | E5: {=_xlfn.LET( _xlpm.kpiName, E$2, _xlpm.factorName, $D5, _xlpm.headerText, "Dependent Variable: "&_xlpm.kpiName, _xlpm.regA, '2A Regression'!$A$1:$A$10000, _xlpm.regB, '2A Regression'!$B$1:$B$10000, _xlpm.regE, '2A Regression'!$E$1:$E$10000, _xlpm.headerRow, MATCH(_xlpm.headerText, _xlpm.regA, 0), _xlpm.nextHeaderRow, _xlfn.AGGREGATE(15, 6, ROW(_xlpm.regA)/((LEFT(_xlpm.regA,19)="Dependent Variable:")*(ROW(_xlpm.regA)>_xlpm.headerRow)), 1), _xlpm.searchStart, _xlpm.headerRow, _xlpm.searchEnd, IF(ISERROR(_xlpm.nextHeaderRow), 300, _xlpm.nextHeaderRow-1), _xlpm.factorPos, _xlfn.AGGREGATE(15, 6, ROW(_xlpm.regB)/((_xlpm.regB=_xlpm.factorName)*(ROW(_xlpm.regB)>=_xlpm.searchStart)*(ROW(_xlpm.regB)<=_xlpm.searchEnd)), 1), IF(ISERROR(_xlpm.factorPos), 0, INDEX(_xlpm.regE, _xlpm.factorPos)) )} | F5: {=_xlfn.LET( _xlpm.kpiName, F$2, _xlpm.factorName, $D5, _xlpm.headerText, "Dependent Variable: "&_xlpm.kpiName, _xlpm.regA, '2A Regression'!$A$1:$A$10000, _xlpm.regB, '2A Regression'!$B$1:$B$10000, _xlpm.regE, '2A Regression'!$E$1:$E$10000, _xlpm.headerRow, MATCH(_xlpm.headerText, _xlpm.regA, 0), _xlpm.nextHeaderRow, _xlfn.AGGREGATE(15, 6, ROW(_xlpm.regA)/((LEFT(_xlpm.regA,19)="Dependent Variable:")*(ROW(_xlpm.regA)>_xlpm.headerRow)), 1), _xlpm.searchStart, _xlpm.headerRow, _xlpm.searchEnd, IF(ISERROR(_xlpm.nextHeaderRow), 300, _xlpm.nextHeaderRow-1), _xlpm.factorPos, _xlfn.AGGREGATE(15, 6, ROW(_xlpm.regB)/((_xlpm.regB=_xlpm.factorName)*(ROW(_xlpm.regB)>=_xlpm.searchStart)*(ROW(_xlpm.regB)<=_xlpm.searchEnd)), 1), IF(ISERROR(_xlpm.factorPos), 0, INDEX(_xlpm.regE, _xlpm.factorPos)) )} | G5: {=_xlfn.LET( _xlpm.kpiName, G$2, _xlpm.factorName, $D5, _xlpm.headerText, "Dependent Variable: "&_xlpm.kpiName, _xlpm.regA, '2A Regression'!$A$1:$A$10000, _xlpm.regB, '2A Regression'!$B$1:$B$10000, _xlpm.regE, '2A Regression'!$E$1:$E$10000, _xlpm.headerRow, MATCH(_xlpm.headerText, _xlpm.regA, 0), _xlpm.nextHeaderRow, _xlfn.AGGREGATE(15, 6, ROW(_xlpm.regA)/((LEFT(_xlpm.regA,19)="Dependent Variable:")*(ROW(_xlpm.regA)>_xlpm.headerRow)), 1), _xlpm.searchStart, _xlpm.headerRow, _xlpm.searchEnd, IF(ISERROR(_xlpm.nextHeaderRow), 300, _xlpm.nextHeaderRow-1), _xlpm.factorPos, _xlfn.AGGREGATE(15, 6, ROW(_xlpm.regB)/((_xlpm.regB=_xlpm.factorName)*(ROW(_xlpm.regB)>=_xlpm.searchStart)*(ROW(_xlpm.regB)<=_xlpm.searchEnd)), 1), IF(ISERROR(_xlpm.factorPos), 0, INDEX(_xlpm.regE, _xlpm.factorPos)) )} | H5: {=_xlfn.LET( _xlpm.kpiName, H$2, _xlpm.factorName, $D5, _xlpm.headerText, "Dependent Variable: "&_xlpm.kpiName, _xlpm.regA, '2A Regression'!$A$1:$A$10000, _xlpm.regB, '2A Regression'!$B$1:$B$10000, _xlpm.regE, '2A Regression'!$E$1:$E$10000, _xlpm.headerRow, MATCH(_xlpm.headerText, _xlpm.regA, 0), _xlpm.nextHeaderRow, _xlfn.AGGREGATE(15, 6, ROW(_xlpm.regA)/((LEFT(_xlpm.regA,19)="Dependent Variable:")*(ROW(_xlpm.regA)>_xlpm.headerRow)), 1), _xlpm.searchStart, _xlpm.headerRow, _xlpm.searchEnd, IF(ISERROR(_xlpm.nextHeaderRow), 300, _xlpm.nextHeaderRow-1), _xlpm.factorPos, _xlfn.AGGREGATE(15, 6, ROW(_xlpm.regB)/((_xlpm.regB=_xlpm.factorName)*(ROW(_xlpm.regB)>=_xlpm.searchStart)*(ROW(_xlpm.regB)<=_xlpm.searchEnd)), 1), IF(ISERROR(_xlpm.factorPos), 0, INDEX(_xlpm.regE, _xlpm.factorPos)) )} | I5: {=_xlfn.LET( _xlpm.kpiName, I$2, _xlpm.factorName, $D5, _xlpm.headerText, "Dependent Variable: "&_xlpm.kpiName, _xlpm.regA, '2A Regression'!$A$1:$A$10000, _xlpm.regB, '2A Regression'!$B$1:$B$10000, _xlpm.regE, '2A Regression'!$E$1:$E$10000, _xlpm.headerRow, MATCH(_xlpm.headerText, _xlpm.regA, 0), _xlpm.nextHeaderRow, _xlfn.AGGREGATE(15, 6, ROW(_xlpm.regA)/((LEFT(_xlpm.regA,19)="Dependent Variable:")*(ROW(_xlpm.regA)>_xlpm.headerRow)), 1), _xlpm.searchStart, _xlpm.headerRow, _xlpm.searchEnd, IF(ISERROR(_xlpm.nextHeaderRow), 300, _xlpm.nextHeaderRow-1), _xlpm.factorPos, _xlfn.AGGREGATE(15, 6, ROW(_xlpm.regB)/((_xlpm.regB=_xlpm.factorName)*(ROW(_xlpm.regB)>=_xlpm.searchStart)*(ROW(_xlpm.regB)<=_xlpm.searchEnd)), 1), IF(ISERROR(_xlpm.factorPos), 0, INDEX(_xlpm.regE, _xlpm.factorPos)) )} | J5: {=_xlfn.LET( _xlpm.kpiName, J$2, _xlpm.factorName, $D5, _xlpm.headerText, "Dependent Variable: "&_xlpm.kpiName, _xlpm.regA, '2A Regression'!$A$1:$A$10000, _xlpm.regB, '2A Regression'!$B$1:$B$10000, _xlpm.regE, '2A Regression'!$E$1:$E$10000, _xlpm.headerRow, MATCH(_xlpm.headerText, _xlpm.regA, 0), _xlpm.nextHeaderRow, _xlfn.AGGREGATE(15, 6, ROW(_xlpm.regA)/((LEFT(_xlpm.regA,19)="Dependent Variable:")*(ROW(_xlpm.regA)>_xlpm.headerRow)), 1), _xlpm.searchStart, _xlpm.headerRow, _xlpm.searchEnd, IF(ISERROR(_xlpm.nextHeaderRow), 300, _xlpm.nextHeaderRow-1), _xlpm.factorPos, _xlfn.AGGREGATE(15, 6, ROW(_xlpm.regB)/((_xlpm.regB=_xlpm.factorName)*(ROW(_xlpm.regB)>=_xlpm.searchStart)*(ROW(_xlpm.regB)<=_xlpm.searchEnd)), 1), IF(ISERROR(_xlpm.factorPos), 0, INDEX(_xlpm.regE, _xlpm.factorPos)) )} | K5: {=_xlfn.LET( _xlpm.kpiName, K$2, _xlpm.factorName, $D5, _xlpm.headerText, "Dependent Variable: "&_xlpm.kpiName, _xlpm.regA, '2A Regression'!$A$1:$A$10000, _xlpm.regB, '2A Regression'!$B$1:$B$10000, _xlpm.regE, '2A Regression'!$E$1:$E$10000, _xlpm.headerRow, MATCH(_xlpm.headerText, _xlpm.regA, 0), _xlpm.nextHeaderRow, _xlfn.AGGREGATE(15, 6, ROW(_xlpm.regA)/((LEFT(_xlpm.regA,19)="Dependent Variable:")*(ROW(_xlpm.regA)>_xlpm.headerRow)), 1), _xlpm.searchStart, _xlpm.headerRow, _xlpm.searchEnd, IF(ISERROR(_xlpm.nextHeaderRow), 300, _xlpm.nextHeaderRow-1), _xlpm.factorPos, _xlfn.AGGREGATE(15, 6, ROW(_xlpm.regB)/((_xlpm.regB=_xlpm.factorName)*(ROW(_xlpm.regB)>=_xlpm.searchStart)*(ROW(_xlpm.regB)<=_xlpm.searchEnd)), 1), IF(ISERROR(_xlpm.factorPos), 0, INDEX(_xlpm.regE, _xlpm.factorPos)) )} | L5: {=_xlfn.LET( _xlpm.kpiName, L$2, _xlpm.factorName, $D5, _xlpm.headerText, "Dependent Variable: "&_xlpm.kpiName, _xlpm.regA, '2A Regression'!$A$1:$A$10000, _xlpm.regB, '2A Regression'!$B$1:$B$10000, _xlpm.regE, '2A Regression'!$E$1:$E$10000, _xlpm.headerRow, MATCH(_xlpm.headerText, _xlpm.regA, 0), _xlpm.nextHeaderRow, _xlfn.AGGREGATE(15, 6, ROW(_xlpm.regA)/((LEFT(_xlpm.regA,19)="Dependent Variable:")*(ROW(_xlpm.regA)>_xlpm.headerRow)), 1), _xlpm.searchStart, _xlpm.headerRow, _xlpm.searchEnd, IF(ISERROR(_xlpm.nextHeaderRow), 300, _xlpm.nextHeaderRow-1), _xlpm.factorPos, _xlfn.AGGREGATE(15, 6, ROW(_xlpm.regB)/((_xlpm.regB=_xlpm.factorName)*(ROW(_xlpm.regB)>=_xlpm.searchStart)*(ROW(_xlpm.regB)<=_xlpm.searchEnd)), 1), IF(ISERROR(_xlpm.factorPos), 0, INDEX(_xlpm.regE, _xlpm.factorPos)) )} | ... BB5: {=_xlfn.LET( _xlpm.kpiName, BB$2, _xlpm.factorName, $D5, _xlpm.headerText, "Dependent Variable: "&_xlpm.kpiName, _xlpm.regA, '2A Regression'!$A$1:$A$10000, _xlpm.regB, '2A Regression'!$B$1:$B$10000, _xlpm.regE, '2A Regression'!$E$1:$E$10000, _xlpm.headerRow, MATCH(_xlpm.headerText, _xlpm.regA, 0), _xlpm.nextHeaderRow, _xlfn.AGGREGATE(15, 6, ROW(_xlpm.regA)/((LEFT(_xlpm.regA,19)="Dependent Variable:")*(ROW(_xlpm.regA)>_xlpm.headerRow)), 1), _xlpm.searchStart, _xlpm.headerRow, _xlpm.searchEnd, IF(ISERROR(_xlpm.nextHeaderRow), 300, _xlpm.nextHeaderRow-1), _xlpm.factorPos, _xlfn.AGGREGATE(15, 6, ROW(_xlpm.regB)/((_xlpm.regB=_xlpm.factorName)*(ROW(_xlpm.regB)>=_xlpm.searchStart)*(ROW(_xlpm.regB)<=_xlpm.searchEnd)), 1), IF(ISERROR(_xlpm.factorPos), 0, INDEX(_xlpm.regE, _xlpm.factorPos)) )}
D6: Factor4 | E6: {=_xlfn.LET( _xlpm.kpiName, E$2, _xlpm.factorName, $D6, _xlpm.headerText, "Dependent Variable: "&_xlpm.kpiName, _xlpm.regA, '2A Regression'!$A$1:$A$10000, _xlpm.regB, '2A Regression'!$B$1:$B$10000, _xlpm.regE, '2A Regression'!$E$1:$E$10000, _xlpm.headerRow, MATCH(_xlpm.headerText, _xlpm.regA, 0), _xlpm.nextHeaderRow, _xlfn.AGGREGATE(15, 6, ROW(_xlpm.regA)/((LEFT(_xlpm.regA,19)="Dependent Variable:")*(ROW(_xlpm.regA)>_xlpm.headerRow)), 1), _xlpm.searchStart, _xlpm.headerRow, _xlpm.searchEnd, IF(ISERROR(_xlpm.nextHeaderRow), 300, _xlpm.nextHeaderRow-1), _xlpm.factorPos, _xlfn.AGGREGATE(15, 6, ROW(_xlpm.regB)/((_xlpm.regB=_xlpm.factorName)*(ROW(_xlpm.regB)>=_xlpm.searchStart)*(ROW(_xlpm.regB)<=_xlpm.searchEnd)), 1), IF(ISERROR(_xlpm.factorPos), 0, INDEX(_xlpm.regE, _xlpm.factorPos)) )} | F6: {=_xlfn.LET( _xlpm.kpiName, F$2, _xlpm.factorName, $D6, _xlpm.headerText, "Dependent Variable: "&_xlpm.kpiName, _xlpm.regA, '2A Regression'!$A$1:$A$10000, _xlpm.regB, '2A Regression'!$B$1:$B$10000, _xlpm.regE, '2A Regression'!$E$1:$E$10000, _xlpm.headerRow, MATCH(_xlpm.headerText, _xlpm.regA, 0), _xlpm.nextHeaderRow, _xlfn.AGGREGATE(15, 6, ROW(_xlpm.regA)/((LEFT(_xlpm.regA,19)="Dependent Variable:")*(ROW(_xlpm.regA)>_xlpm.headerRow)), 1), _xlpm.searchStart, _xlpm.headerRow, _xlpm.searchEnd, IF(ISERROR(_xlpm.nextHeaderRow), 300, _xlpm.nextHeaderRow-1), _xlpm.factorPos, _xlfn.AGGREGATE(15, 6, ROW(_xlpm.regB)/((_xlpm.regB=_xlpm.factorName)*(ROW(_xlpm.regB)>=_xlpm.searchStart)*(ROW(_xlpm.regB)<=_xlpm.searchEnd)), 1), IF(ISERROR(_xlpm.factorPos), 0, INDEX(_xlpm.regE, _xlpm.factorPos)) )} | G6: {=_xlfn.LET( _xlpm.kpiName, G$2, _xlpm.factorName, $D6, _xlpm.headerText, "Dependent Variable: "&_xlpm.kpiName, _xlpm.regA, '2A Regression'!$A$1:$A$10000, _xlpm.regB, '2A Regression'!$B$1:$B$10000, _xlpm.regE, '2A Regression'!$E$1:$E$10000, _xlpm.headerRow, MATCH(_xlpm.headerText, _xlpm.regA, 0), _xlpm.nextHeaderRow, _xlfn.AGGREGATE(15, 6, ROW(_xlpm.regA)/((LEFT(_xlpm.regA,19)="Dependent Variable:")*(ROW(_xlpm.regA)>_xlpm.headerRow)), 1), _xlpm.searchStart, _xlpm.headerRow, _xlpm.searchEnd, IF(ISERROR(_xlpm.nextHeaderRow), 300, _xlpm.nextHeaderRow-1), _xlpm.factorPos, _xlfn.AGGREGATE(15, 6, ROW(_xlpm.regB)/((_xlpm.regB=_xlpm.factorName)*(ROW(_xlpm.regB)>=_xlpm.searchStart)*(ROW(_xlpm.regB)<=_xlpm.searchEnd)), 1), IF(ISERROR(_xlpm.factorPos), 0, INDEX(_xlpm.regE, _xlpm.factorPos)) )} | H6: {=_xlfn.LET( _xlpm.kpiName, H$2, _xlpm.factorName, $D6, _xlpm.headerText, "Dependent Variable: "&_xlpm.kpiName, _xlpm.regA, '2A Regression'!$A$1:$A$10000, _xlpm.regB, '2A Regression'!$B$1:$B$10000, _xlpm.regE, '2A Regression'!$E$1:$E$10000, _xlpm.headerRow, MATCH(_xlpm.headerText, _xlpm.regA, 0), _xlpm.nextHeaderRow, _xlfn.AGGREGATE(15, 6, ROW(_xlpm.regA)/((LEFT(_xlpm.regA,19)="Dependent Variable:")*(ROW(_xlpm.regA)>_xlpm.headerRow)), 1), _xlpm.searchStart, _xlpm.headerRow, _xlpm.searchEnd, IF(ISERROR(_xlpm.nextHeaderRow), 300, _xlpm.nextHeaderRow-1), _xlpm.factorPos, _xlfn.AGGREGATE(15, 6, ROW(_xlpm.regB)/((_xlpm.regB=_xlpm.factorName)*(ROW(_xlpm.regB)>=_xlpm.searchStart)*(ROW(_xlpm.regB)<=_xlpm.searchEnd)), 1), IF(ISERROR(_xlpm.factorPos), 0, INDEX(_xlpm.regE, _xlpm.factorPos)) )} | I6: {=_xlfn.LET( _xlpm.kpiName, I$2, _xlpm.factorName, $D6, _xlpm.headerText, "Dependent Variable: "&_xlpm.kpiName, _xlpm.regA, '2A Regression'!$A$1:$A$10000, _xlpm.regB, '2A Regression'!$B$1:$B$10000, _xlpm.regE, '2A Regression'!$E$1:$E$10000, _xlpm.headerRow, MATCH(_xlpm.headerText, _xlpm.regA, 0), _xlpm.nextHeaderRow, _xlfn.AGGREGATE(15, 6, ROW(_xlpm.regA)/((LEFT(_xlpm.regA,19)="Dependent Variable:")*(ROW(_xlpm.regA)>_xlpm.headerRow)), 1), _xlpm.searchStart, _xlpm.headerRow, _xlpm.searchEnd, IF(ISERROR(_xlpm.nextHeaderRow), 300, _xlpm.nextHeaderRow-1), _xlpm.factorPos, _xlfn.AGGREGATE(15, 6, ROW(_xlpm.regB)/((_xlpm.regB=_xlpm.factorName)*(ROW(_xlpm.regB)>=_xlpm.searchStart)*(ROW(_xlpm.regB)<=_xlpm.searchEnd)), 1), IF(ISERROR(_xlpm.factorPos), 0, INDEX(_xlpm.regE, _xlpm.factorPos)) )} | J6: {=_xlfn.LET( _xlpm.kpiName, J$2, _xlpm.factorName, $D6, _xlpm.headerText, "Dependent Variable: "&_xlpm.kpiName, _xlpm.regA, '2A Regression'!$A$1:$A$10000, _xlpm.regB, '2A Regression'!$B$1:$B$10000, _xlpm.regE, '2A Regression'!$E$1:$E$10000, _xlpm.headerRow, MATCH(_xlpm.headerText, _xlpm.regA, 0), _xlpm.nextHeaderRow, _xlfn.AGGREGATE(15, 6, ROW(_xlpm.regA)/((LEFT(_xlpm.regA,19)="Dependent Variable:")*(ROW(_xlpm.regA)>_xlpm.headerRow)), 1), _xlpm.searchStart, _xlpm.headerRow, _xlpm.searchEnd, IF(ISERROR(_xlpm.nextHeaderRow), 300, _xlpm.nextHeaderRow-1), _xlpm.factorPos, _xlfn.AGGREGATE(15, 6, ROW(_xlpm.regB)/((_xlpm.regB=_xlpm.factorName)*(ROW(_xlpm.regB)>=_xlpm.searchStart)*(ROW(_xlpm.regB)<=_xlpm.searchEnd)), 1), IF(ISERROR(_xlpm.factorPos), 0, INDEX(_xlpm.regE, _xlpm.factorPos)) )} | K6: {=_xlfn.LET( _xlpm.kpiName, K$2, _xlpm.factorName, $D6, _xlpm.headerText, "Dependent Variable: "&_xlpm.kpiName, _xlpm.regA, '2A Regression'!$A$1:$A$10000, _xlpm.regB, '2A Regression'!$B$1:$B$10000, _xlpm.regE, '2A Regression'!$E$1:$E$10000, _xlpm.headerRow, MATCH(_xlpm.headerText, _xlpm.regA, 0), _xlpm.nextHeaderRow, _xlfn.AGGREGATE(15, 6, ROW(_xlpm.regA)/((LEFT(_xlpm.regA,19)="Dependent Variable:")*(ROW(_xlpm.regA)>_xlpm.headerRow)), 1), _xlpm.searchStart, _xlpm.headerRow, _xlpm.searchEnd, IF(ISERROR(_xlpm.nextHeaderRow), 300, _xlpm.nextHeaderRow-1), _xlpm.factorPos, _xlfn.AGGREGATE(15, 6, ROW(_xlpm.regB)/((_xlpm.regB=_xlpm.factorName)*(ROW(_xlpm.regB)>=_xlpm.searchStart)*(ROW(_xlpm.regB)<=_xlpm.searchEnd)), 1), IF(ISERROR(_xlpm.factorPos), 0, INDEX(_xlpm.regE, _xlpm.factorPos)) )} | L6: {=_xlfn.LET( _xlpm.kpiName, L$2, _xlpm.factorName, $D6, _xlpm.headerText, "Dependent Variable: "&_xlpm.kpiName, _xlpm.regA, '2A Regression'!$A$1:$A$10000, _xlpm.regB, '2A Regression'!$B$1:$B$10000, _xlpm.regE, '2A Regression'!$E$1:$E$10000, _xlpm.headerRow, MATCH(_xlpm.headerText, _xlpm.regA, 0), _xlpm.nextHeaderRow, _xlfn.AGGREGATE(15, 6, ROW(_xlpm.regA)/((LEFT(_xlpm.regA,19)="Dependent Variable:")*(ROW(_xlpm.regA)>_xlpm.headerRow)), 1), _xlpm.searchStart, _xlpm.headerRow, _xlpm.searchEnd, IF(ISERROR(_xlpm.nextHeaderRow), 300, _xlpm.nextHeaderRow-1), _xlpm.factorPos, _xlfn.AGGREGATE(15, 6, ROW(_xlpm.regB)/((_xlpm.regB=_xlpm.factorName)*(ROW(_xlpm.regB)>=_xlpm.searchStart)*(ROW(_xlpm.regB)<=_xlpm.searchEnd)), 1), IF(ISERROR(_xlpm.factorPos), 0, INDEX(_xlpm.regE, _xlpm.factorPos)) )} | ... BB6: {=_xlfn.LET( _xlpm.kpiName, BB$2, _xlpm.factorName, $D6, _xlpm.headerText, "Dependent Variable: "&_xlpm.kpiName, _xlpm.regA, '2A Regression'!$A$1:$A$10000, _xlpm.regB, '2A Regression'!$B$1:$B$10000, _xlpm.regE, '2A Regression'!$E$1:$E$10000, _xlpm.headerRow, MATCH(_xlpm.headerText, _xlpm.regA, 0), _xlpm.nextHeaderRow, _xlfn.AGGREGATE(15, 6, ROW(_xlpm.regA)/((LEFT(_xlpm.regA,19)="Dependent Variable:")*(ROW(_xlpm.regA)>_xlpm.headerRow)), 1), _xlpm.searchStart, _xlpm.headerRow, _xlpm.searchEnd, IF(ISERROR(_xlpm.nextHeaderRow), 300, _xlpm.nextHeaderRow-1), _xlpm.factorPos, _xlfn.AGGREGATE(15, 6, ROW(_xlpm.regB)/((_xlpm.regB=_xlpm.factorName)*(ROW(_xlpm.regB)>=_xlpm.searchStart)*(ROW(_xlpm.regB)<=_xlpm.searchEnd)), 1), IF(ISERROR(_xlpm.factorPos), 0, INDEX(_xlpm.regE, _xlpm.factorPos)) )}
D7: Factor5 | E7: {=_xlfn.LET( _xlpm.kpiName, E$2, _xlpm.factorName, $D7, _xlpm.headerText, "Dependent Variable: "&_xlpm.kpiName, _xlpm.regA, '2A Regression'!$A$1:$A$10000, _xlpm.regB, '2A Regression'!$B$1:$B$10000, _xlpm.regE, '2A Regression'!$E$1:$E$10000, _xlpm.headerRow, MATCH(_xlpm.headerText, _xlpm.regA, 0), _xlpm.nextHeaderRow, _xlfn.AGGREGATE(15, 6, ROW(_xlpm.regA)/((LEFT(_xlpm.regA,19)="Dependent Variable:")*(ROW(_xlpm.regA)>_xlpm.headerRow)), 1), _xlpm.searchStart, _xlpm.headerRow, _xlpm.searchEnd, IF(ISERROR(_xlpm.nextHeaderRow), 300, _xlpm.nextHeaderRow-1), _xlpm.factorPos, _xlfn.AGGREGATE(15, 6, ROW(_xlpm.regB)/((_xlpm.regB=_xlpm.factorName)*(ROW(_xlpm.regB)>=_xlpm.searchStart)*(ROW(_xlpm.regB)<=_xlpm.searchEnd)), 1), IF(ISERROR(_xlpm.factorPos), 0, INDEX(_xlpm.regE, _xlpm.factorPos)) )} | F7: {=_xlfn.LET( _xlpm.kpiName, F$2, _xlpm.factorName, $D7, _xlpm.headerText, "Dependent Variable: "&_xlpm.kpiName, _xlpm.regA, '2A Regression'!$A$1:$A$10000, _xlpm.regB, '2A Regression'!$B$1:$B$10000, _xlpm.regE, '2A Regression'!$E$1:$E$10000, _xlpm.headerRow, MATCH(_xlpm.headerText, _xlpm.regA, 0), _xlpm.nextHeaderRow, _xlfn.AGGREGATE(15, 6, ROW(_xlpm.regA)/((LEFT(_xlpm.regA,19)="Dependent Variable:")*(ROW(_xlpm.regA)>_xlpm.headerRow)), 1), _xlpm.searchStart, _xlpm.headerRow, _xlpm.searchEnd, IF(ISERROR(_xlpm.nextHeaderRow), 300, _xlpm.nextHeaderRow-1), _xlpm.factorPos, _xlfn.AGGREGATE(15, 6, ROW(_xlpm.regB)/((_xlpm.regB=_xlpm.factorName)*(ROW(_xlpm.regB)>=_xlpm.searchStart)*(ROW(_xlpm.regB)<=_xlpm.searchEnd)), 1), IF(ISERROR(_xlpm.factorPos), 0, INDEX(_xlpm.regE, _xlpm.factorPos)) )} | G7: {=_xlfn.LET( _xlpm.kpiName, G$2, _xlpm.factorName, $D7, _xlpm.headerText, "Dependent Variable: "&_xlpm.kpiName, _xlpm.regA, '2A Regression'!$A$1:$A$10000, _xlpm.regB, '2A Regression'!$B$1:$B$10000, _xlpm.regE, '2A Regression'!$E$1:$E$10000, _xlpm.headerRow, MATCH(_xlpm.headerText, _xlpm.regA, 0), _xlpm.nextHeaderRow, _xlfn.AGGREGATE(15, 6, ROW(_xlpm.regA)/((LEFT(_xlpm.regA,19)="Dependent Variable:")*(ROW(_xlpm.regA)>_xlpm.headerRow)), 1), _xlpm.searchStart, _xlpm.headerRow, _xlpm.searchEnd, IF(ISERROR(_xlpm.nextHeaderRow), 300, _xlpm.nextHeaderRow-1), _xlpm.factorPos, _xlfn.AGGREGATE(15, 6, ROW(_xlpm.regB)/((_xlpm.regB=_xlpm.factorName)*(ROW(_xlpm.regB)>=_xlpm.searchStart)*(ROW(_xlpm.regB)<=_xlpm.searchEnd)), 1), IF(ISERROR(_xlpm.factorPos), 0, INDEX(_xlpm.regE, _xlpm.factorPos)) )} | H7: {=_xlfn.LET( _xlpm.kpiName, H$2, _xlpm.factorName, $D7, _xlpm.headerText, "Dependent Variable: "&_xlpm.kpiName, _xlpm.regA, '2A Regression'!$A$1:$A$10000, _xlpm.regB, '2A Regression'!$B$1:$B$10000, _xlpm.regE, '2A Regression'!$E$1:$E$10000, _xlpm.headerRow, MATCH(_xlpm.headerText, _xlpm.regA, 0), _xlpm.nextHeaderRow, _xlfn.AGGREGATE(15, 6, ROW(_xlpm.regA)/((LEFT(_xlpm.regA,19)="Dependent Variable:")*(ROW(_xlpm.regA)>_xlpm.headerRow)), 1), _xlpm.searchStart, _xlpm.headerRow, _xlpm.searchEnd, IF(ISERROR(_xlpm.nextHeaderRow), 300, _xlpm.nextHeaderRow-1), _xlpm.factorPos, _xlfn.AGGREGATE(15, 6, ROW(_xlpm.regB)/((_xlpm.regB=_xlpm.factorName)*(ROW(_xlpm.regB)>=_xlpm.searchStart)*(ROW(_xlpm.regB)<=_xlpm.searchEnd)), 1), IF(ISERROR(_xlpm.factorPos), 0, INDEX(_xlpm.regE, _xlpm.factorPos)) )} | I7: {=_xlfn.LET( _xlpm.kpiName, I$2, _xlpm.factorName, $D7, _xlpm.headerText, "Dependent Variable: "&_xlpm.kpiName, _xlpm.regA, '2A Regression'!$A$1:$A$10000, _xlpm.regB, '2A Regression'!$B$1:$B$10000, _xlpm.regE, '2A Regression'!$E$1:$E$10000, _xlpm.headerRow, MATCH(_xlpm.headerText, _xlpm.regA, 0), _xlpm.nextHeaderRow, _xlfn.AGGREGATE(15, 6, ROW(_xlpm.regA)/((LEFT(_xlpm.regA,19)="Dependent Variable:")*(ROW(_xlpm.regA)>_xlpm.headerRow)), 1), _xlpm.searchStart, _xlpm.headerRow, _xlpm.searchEnd, IF(ISERROR(_xlpm.nextHeaderRow), 300, _xlpm.nextHeaderRow-1), _xlpm.factorPos, _xlfn.AGGREGATE(15, 6, ROW(_xlpm.regB)/((_xlpm.regB=_xlpm.factorName)*(ROW(_xlpm.regB)>=_xlpm.searchStart)*(ROW(_xlpm.regB)<=_xlpm.searchEnd)), 1), IF(ISERROR(_xlpm.factorPos), 0, INDEX(_xlpm.regE, _xlpm.factorPos)) )} | J7: {=_xlfn.LET( _xlpm.kpiName, J$2, _xlpm.factorName, $D7, _xlpm.headerText, "Dependent Variable: "&_xlpm.kpiName, _xlpm.regA, '2A Regression'!$A$1:$A$10000, _xlpm.regB, '2A Regression'!$B$1:$B$10000, _xlpm.regE, '2A Regression'!$E$1:$E$10000, _xlpm.headerRow, MATCH(_xlpm.headerText, _xlpm.regA, 0), _xlpm.nextHeaderRow, _xlfn.AGGREGATE(15, 6, ROW(_xlpm.regA)/((LEFT(_xlpm.regA,19)="Dependent Variable:")*(ROW(_xlpm.regA)>_xlpm.headerRow)), 1), _xlpm.searchStart, _xlpm.headerRow, _xlpm.searchEnd, IF(ISERROR(_xlpm.nextHeaderRow), 300, _xlpm.nextHeaderRow-1), _xlpm.factorPos, _xlfn.AGGREGATE(15, 6, ROW(_xlpm.regB)/((_xlpm.regB=_xlpm.factorName)*(ROW(_xlpm.regB)>=_xlpm.searchStart)*(ROW(_xlpm.regB)<=_xlpm.searchEnd)), 1), IF(ISERROR(_xlpm.factorPos), 0, INDEX(_xlpm.regE, _xlpm.factorPos)) )} | K7: {=_xlfn.LET( _xlpm.kpiName, K$2, _xlpm.factorName, $D7, _xlpm.headerText, "Dependent Variable: "&_xlpm.kpiName, _xlpm.regA, '2A Regression'!$A$1:$A$10000, _xlpm.regB, '2A Regression'!$B$1:$B$10000, _xlpm.regE, '2A Regression'!$E$1:$E$10000, _xlpm.headerRow, MATCH(_xlpm.headerText, _xlpm.regA, 0), _xlpm.nextHeaderRow, _xlfn.AGGREGATE(15, 6, ROW(_xlpm.regA)/((LEFT(_xlpm.regA,19)="Dependent Variable:")*(ROW(_xlpm.regA)>_xlpm.headerRow)), 1), _xlpm.searchStart, _xlpm.headerRow, _xlpm.searchEnd, IF(ISERROR(_xlpm.nextHeaderRow), 300, _xlpm.nextHeaderRow-1), _xlpm.factorPos, _xlfn.AGGREGATE(15, 6, ROW(_xlpm.regB)/((_xlpm.regB=_xlpm.factorName)*(ROW(_xlpm.regB)>=_xlpm.searchStart)*(ROW(_xlpm.regB)<=_xlpm.searchEnd)), 1), IF(ISERROR(_xlpm.factorPos), 0, INDEX(_xlpm.regE, _xlpm.factorPos)) )} | L7: {=_xlfn.LET( _xlpm.kpiName, L$2, _xlpm.factorName, $D7, _xlpm.headerText, "Dependent Variable: "&_xlpm.kpiName, _xlpm.regA, '2A Regression'!$A$1:$A$10000, _xlpm.regB, '2A Regression'!$B$1:$B$10000, _xlpm.regE, '2A Regression'!$E$1:$E$10000, _xlpm.headerRow, MATCH(_xlpm.headerText, _xlpm.regA, 0), _xlpm.nextHeaderRow, _xlfn.AGGREGATE(15, 6, ROW(_xlpm.regA)/((LEFT(_xlpm.regA,19)="Dependent Variable:")*(ROW(_xlpm.regA)>_xlpm.headerRow)), 1), _xlpm.searchStart, _xlpm.headerRow, _xlpm.searchEnd, IF(ISERROR(_xlpm.nextHeaderRow), 300, _xlpm.nextHeaderRow-1), _xlpm.factorPos, _xlfn.AGGREGATE(15, 6, ROW(_xlpm.regB)/((_xlpm.regB=_xlpm.factorName)*(ROW(_xlpm.regB)>=_xlpm.searchStart)*(ROW(_xlpm.regB)<=_xlpm.searchEnd)), 1), IF(ISERROR(_xlpm.factorPos), 0, INDEX(_xlpm.regE, _xlpm.factorPos)) )} | ... BB7: {=_xlfn.LET( _xlpm.kpiName, BB$2, _xlpm.factorName, $D7, _xlpm.headerText, "Dependent Variable: "&_xlpm.kpiName, _xlpm.regA, '2A Regression'!$A$1:$A$10000, _xlpm.regB, '2A Regression'!$B$1:$B$10000, _xlpm.regE, '2A Regression'!$E$1:$E$10000, _xlpm.headerRow, MATCH(_xlpm.headerText, _xlpm.regA, 0), _xlpm.nextHeaderRow, _xlfn.AGGREGATE(15, 6, ROW(_xlpm.regA)/((LEFT(_xlpm.regA,19)="Dependent Variable:")*(ROW(_xlpm.regA)>_xlpm.headerRow)), 1), _xlpm.searchStart, _xlpm.headerRow, _xlpm.searchEnd, IF(ISERROR(_xlpm.nextHeaderRow), 300, _xlpm.nextHeaderRow-1), _xlpm.factorPos, _xlfn.AGGREGATE(15, 6, ROW(_xlpm.regB)/((_xlpm.regB=_xlpm.factorName)*(ROW(_xlpm.regB)>=_xlpm.searchStart)*(ROW(_xlpm.regB)<=_xlpm.searchEnd)), 1), IF(ISERROR(_xlpm.factorPos), 0, INDEX(_xlpm.regE, _xlpm.factorPos)) )}
